{
  "nbformat": 4,
  "nbformat_minor": 0,
  "metadata": {
    "colab": {
      "provenance": []
    },
    "kernelspec": {
      "name": "python3",
      "display_name": "Python 3"
    },
    "language_info": {
      "name": "python"
    }
  },
  "cells": [
    {
      "cell_type": "code",
      "source": [],
      "metadata": {
        "id": "Z9sYcDE-qV7z"
      },
      "execution_count": null,
      "outputs": []
    },
    {
      "cell_type": "markdown",
      "source": [
        "# 1.) Import an asset price from Yahoo Finance"
      ],
      "metadata": {
        "id": "6dJuZDx9qWeM"
      }
    },
    {
      "cell_type": "code",
      "source": [
        "pip install yfinance"
      ],
      "metadata": {
        "colab": {
          "base_uri": "https://localhost:8080/"
        },
        "id": "QxUUnTVTrx3m",
        "outputId": "5c609222-5a67-4f39-9b50-95227c0b4c3f"
      },
      "execution_count": 1,
      "outputs": [
        {
          "output_type": "stream",
          "name": "stdout",
          "text": [
            "Looking in indexes: https://pypi.org/simple, https://us-python.pkg.dev/colab-wheels/public/simple/\n",
            "Requirement already satisfied: yfinance in /usr/local/lib/python3.8/dist-packages (0.2.12)\n",
            "Requirement already satisfied: multitasking>=0.0.7 in /usr/local/lib/python3.8/dist-packages (from yfinance) (0.0.11)\n",
            "Requirement already satisfied: requests>=2.26 in /usr/local/lib/python3.8/dist-packages (from yfinance) (2.28.2)\n",
            "Requirement already satisfied: beautifulsoup4>=4.11.1 in /usr/local/lib/python3.8/dist-packages (from yfinance) (4.11.2)\n",
            "Requirement already satisfied: cryptography>=3.3.2 in /usr/local/lib/python3.8/dist-packages (from yfinance) (39.0.1)\n",
            "Requirement already satisfied: numpy>=1.16.5 in /usr/local/lib/python3.8/dist-packages (from yfinance) (1.22.4)\n",
            "Requirement already satisfied: lxml>=4.9.1 in /usr/local/lib/python3.8/dist-packages (from yfinance) (4.9.2)\n",
            "Requirement already satisfied: pandas>=1.3.0 in /usr/local/lib/python3.8/dist-packages (from yfinance) (1.3.5)\n",
            "Requirement already satisfied: appdirs>=1.4.4 in /usr/local/lib/python3.8/dist-packages (from yfinance) (1.4.4)\n",
            "Requirement already satisfied: pytz>=2022.5 in /usr/local/lib/python3.8/dist-packages (from yfinance) (2022.7.1)\n",
            "Requirement already satisfied: frozendict>=2.3.4 in /usr/local/lib/python3.8/dist-packages (from yfinance) (2.3.5)\n",
            "Requirement already satisfied: html5lib>=1.1 in /usr/local/lib/python3.8/dist-packages (from yfinance) (1.1)\n",
            "Requirement already satisfied: soupsieve>1.2 in /usr/local/lib/python3.8/dist-packages (from beautifulsoup4>=4.11.1->yfinance) (2.4)\n",
            "Requirement already satisfied: cffi>=1.12 in /usr/local/lib/python3.8/dist-packages (from cryptography>=3.3.2->yfinance) (1.15.1)\n",
            "Requirement already satisfied: webencodings in /usr/local/lib/python3.8/dist-packages (from html5lib>=1.1->yfinance) (0.5.1)\n",
            "Requirement already satisfied: six>=1.9 in /usr/local/lib/python3.8/dist-packages (from html5lib>=1.1->yfinance) (1.15.0)\n",
            "Requirement already satisfied: python-dateutil>=2.7.3 in /usr/local/lib/python3.8/dist-packages (from pandas>=1.3.0->yfinance) (2.8.2)\n",
            "Requirement already satisfied: charset-normalizer<4,>=2 in /usr/local/lib/python3.8/dist-packages (from requests>=2.26->yfinance) (3.0.1)\n",
            "Requirement already satisfied: urllib3<1.27,>=1.21.1 in /usr/local/lib/python3.8/dist-packages (from requests>=2.26->yfinance) (1.24.3)\n",
            "Requirement already satisfied: idna<4,>=2.5 in /usr/local/lib/python3.8/dist-packages (from requests>=2.26->yfinance) (2.10)\n",
            "Requirement already satisfied: certifi>=2017.4.17 in /usr/local/lib/python3.8/dist-packages (from requests>=2.26->yfinance) (2022.12.7)\n",
            "Requirement already satisfied: pycparser in /usr/local/lib/python3.8/dist-packages (from cffi>=1.12->cryptography>=3.3.2->yfinance) (2.21)\n"
          ]
        }
      ]
    },
    {
      "cell_type": "code",
      "execution_count": 2,
      "metadata": {
        "colab": {
          "base_uri": "https://localhost:8080/"
        },
        "id": "Y3bcwJb4rp93",
        "outputId": "e49df478-4f40-42e7-eff5-ae5332e6ae6c"
      },
      "outputs": [
        {
          "output_type": "stream",
          "name": "stdout",
          "text": [
            "\r[*********************100%***********************]  1 of 1 completed\n"
          ]
        }
      ],
      "source": [
        "import yfinance as yf\n",
        "import numpy as np\n",
        "import pandas as pd\n",
        "from sklearn.preprocessing import MinMaxScaler\n",
        "from tensorflow.keras.models import Sequential\n",
        "from tensorflow.keras.layers import Dense, LSTM, Dropout\n",
        "\n",
        "\n",
        "########################################\n",
        "####Pick your ticker and time period####\n",
        "########################################\n",
        "stock_data = yf.download(\"BABA\", start=\"2014-09-19\", end=\"2022-09-19\")\n",
        "\n",
        "\n",
        "\n",
        "# Preprocess data\n",
        "scaled_data = np.array(stock_data[\"Close\"].pct_change().dropna()).reshape(-1,1)\n",
        "\n",
        "\n",
        "# Split data into training and test sets\n",
        "training_data_len = int(len(scaled_data) * 0.8)\n",
        "train_data = scaled_data[0:training_data_len, :]\n",
        "\n"
      ]
    },
    {
      "cell_type": "code",
      "source": [
        "stock_data"
      ],
      "metadata": {
        "colab": {
          "base_uri": "https://localhost:8080/",
          "height": 455
        },
        "id": "Vr6f3rh5J5eA",
        "outputId": "3b141ce7-d717-4b18-d108-813fde2409ad"
      },
      "execution_count": 3,
      "outputs": [
        {
          "output_type": "execute_result",
          "data": {
            "text/plain": [
              "                 Open       High        Low      Close  Adj Close     Volume\n",
              "Date                                                                        \n",
              "2014-09-19  92.699997  99.699997  89.949997  93.889999  93.889999  271879400\n",
              "2014-09-22  92.699997  92.949997  89.500000  89.889999  89.889999   66657800\n",
              "2014-09-23  88.940002  90.480003  86.620003  87.169998  87.169998   39009800\n",
              "2014-09-24  88.470001  90.570000  87.220001  90.570000  90.570000   32088000\n",
              "2014-09-25  91.089996  91.500000  88.500000  88.919998  88.919998   28598000\n",
              "...               ...        ...        ...        ...        ...        ...\n",
              "2022-09-12  92.419998  94.839996  91.809998  94.690002  94.690002   15604000\n",
              "2022-09-13  90.760002  92.180000  89.230003  89.470001  89.470001   21149800\n",
              "2022-09-14  89.459999  89.779999  88.169998  88.919998  88.919998   10843600\n",
              "2022-09-15  88.629997  91.095001  88.199997  88.830002  88.830002   12188800\n",
              "2022-09-16  87.699997  88.250000  85.419998  86.430000  86.430000   19322000\n",
              "\n",
              "[2013 rows x 6 columns]"
            ],
            "text/html": [
              "\n",
              "  <div id=\"df-0ea7bea3-9990-40cd-bef7-09457f51b922\">\n",
              "    <div class=\"colab-df-container\">\n",
              "      <div>\n",
              "<style scoped>\n",
              "    .dataframe tbody tr th:only-of-type {\n",
              "        vertical-align: middle;\n",
              "    }\n",
              "\n",
              "    .dataframe tbody tr th {\n",
              "        vertical-align: top;\n",
              "    }\n",
              "\n",
              "    .dataframe thead th {\n",
              "        text-align: right;\n",
              "    }\n",
              "</style>\n",
              "<table border=\"1\" class=\"dataframe\">\n",
              "  <thead>\n",
              "    <tr style=\"text-align: right;\">\n",
              "      <th></th>\n",
              "      <th>Open</th>\n",
              "      <th>High</th>\n",
              "      <th>Low</th>\n",
              "      <th>Close</th>\n",
              "      <th>Adj Close</th>\n",
              "      <th>Volume</th>\n",
              "    </tr>\n",
              "    <tr>\n",
              "      <th>Date</th>\n",
              "      <th></th>\n",
              "      <th></th>\n",
              "      <th></th>\n",
              "      <th></th>\n",
              "      <th></th>\n",
              "      <th></th>\n",
              "    </tr>\n",
              "  </thead>\n",
              "  <tbody>\n",
              "    <tr>\n",
              "      <th>2014-09-19</th>\n",
              "      <td>92.699997</td>\n",
              "      <td>99.699997</td>\n",
              "      <td>89.949997</td>\n",
              "      <td>93.889999</td>\n",
              "      <td>93.889999</td>\n",
              "      <td>271879400</td>\n",
              "    </tr>\n",
              "    <tr>\n",
              "      <th>2014-09-22</th>\n",
              "      <td>92.699997</td>\n",
              "      <td>92.949997</td>\n",
              "      <td>89.500000</td>\n",
              "      <td>89.889999</td>\n",
              "      <td>89.889999</td>\n",
              "      <td>66657800</td>\n",
              "    </tr>\n",
              "    <tr>\n",
              "      <th>2014-09-23</th>\n",
              "      <td>88.940002</td>\n",
              "      <td>90.480003</td>\n",
              "      <td>86.620003</td>\n",
              "      <td>87.169998</td>\n",
              "      <td>87.169998</td>\n",
              "      <td>39009800</td>\n",
              "    </tr>\n",
              "    <tr>\n",
              "      <th>2014-09-24</th>\n",
              "      <td>88.470001</td>\n",
              "      <td>90.570000</td>\n",
              "      <td>87.220001</td>\n",
              "      <td>90.570000</td>\n",
              "      <td>90.570000</td>\n",
              "      <td>32088000</td>\n",
              "    </tr>\n",
              "    <tr>\n",
              "      <th>2014-09-25</th>\n",
              "      <td>91.089996</td>\n",
              "      <td>91.500000</td>\n",
              "      <td>88.500000</td>\n",
              "      <td>88.919998</td>\n",
              "      <td>88.919998</td>\n",
              "      <td>28598000</td>\n",
              "    </tr>\n",
              "    <tr>\n",
              "      <th>...</th>\n",
              "      <td>...</td>\n",
              "      <td>...</td>\n",
              "      <td>...</td>\n",
              "      <td>...</td>\n",
              "      <td>...</td>\n",
              "      <td>...</td>\n",
              "    </tr>\n",
              "    <tr>\n",
              "      <th>2022-09-12</th>\n",
              "      <td>92.419998</td>\n",
              "      <td>94.839996</td>\n",
              "      <td>91.809998</td>\n",
              "      <td>94.690002</td>\n",
              "      <td>94.690002</td>\n",
              "      <td>15604000</td>\n",
              "    </tr>\n",
              "    <tr>\n",
              "      <th>2022-09-13</th>\n",
              "      <td>90.760002</td>\n",
              "      <td>92.180000</td>\n",
              "      <td>89.230003</td>\n",
              "      <td>89.470001</td>\n",
              "      <td>89.470001</td>\n",
              "      <td>21149800</td>\n",
              "    </tr>\n",
              "    <tr>\n",
              "      <th>2022-09-14</th>\n",
              "      <td>89.459999</td>\n",
              "      <td>89.779999</td>\n",
              "      <td>88.169998</td>\n",
              "      <td>88.919998</td>\n",
              "      <td>88.919998</td>\n",
              "      <td>10843600</td>\n",
              "    </tr>\n",
              "    <tr>\n",
              "      <th>2022-09-15</th>\n",
              "      <td>88.629997</td>\n",
              "      <td>91.095001</td>\n",
              "      <td>88.199997</td>\n",
              "      <td>88.830002</td>\n",
              "      <td>88.830002</td>\n",
              "      <td>12188800</td>\n",
              "    </tr>\n",
              "    <tr>\n",
              "      <th>2022-09-16</th>\n",
              "      <td>87.699997</td>\n",
              "      <td>88.250000</td>\n",
              "      <td>85.419998</td>\n",
              "      <td>86.430000</td>\n",
              "      <td>86.430000</td>\n",
              "      <td>19322000</td>\n",
              "    </tr>\n",
              "  </tbody>\n",
              "</table>\n",
              "<p>2013 rows × 6 columns</p>\n",
              "</div>\n",
              "      <button class=\"colab-df-convert\" onclick=\"convertToInteractive('df-0ea7bea3-9990-40cd-bef7-09457f51b922')\"\n",
              "              title=\"Convert this dataframe to an interactive table.\"\n",
              "              style=\"display:none;\">\n",
              "        \n",
              "  <svg xmlns=\"http://www.w3.org/2000/svg\" height=\"24px\"viewBox=\"0 0 24 24\"\n",
              "       width=\"24px\">\n",
              "    <path d=\"M0 0h24v24H0V0z\" fill=\"none\"/>\n",
              "    <path d=\"M18.56 5.44l.94 2.06.94-2.06 2.06-.94-2.06-.94-.94-2.06-.94 2.06-2.06.94zm-11 1L8.5 8.5l.94-2.06 2.06-.94-2.06-.94L8.5 2.5l-.94 2.06-2.06.94zm10 10l.94 2.06.94-2.06 2.06-.94-2.06-.94-.94-2.06-.94 2.06-2.06.94z\"/><path d=\"M17.41 7.96l-1.37-1.37c-.4-.4-.92-.59-1.43-.59-.52 0-1.04.2-1.43.59L10.3 9.45l-7.72 7.72c-.78.78-.78 2.05 0 2.83L4 21.41c.39.39.9.59 1.41.59.51 0 1.02-.2 1.41-.59l7.78-7.78 2.81-2.81c.8-.78.8-2.07 0-2.86zM5.41 20L4 18.59l7.72-7.72 1.47 1.35L5.41 20z\"/>\n",
              "  </svg>\n",
              "      </button>\n",
              "      \n",
              "  <style>\n",
              "    .colab-df-container {\n",
              "      display:flex;\n",
              "      flex-wrap:wrap;\n",
              "      gap: 12px;\n",
              "    }\n",
              "\n",
              "    .colab-df-convert {\n",
              "      background-color: #E8F0FE;\n",
              "      border: none;\n",
              "      border-radius: 50%;\n",
              "      cursor: pointer;\n",
              "      display: none;\n",
              "      fill: #1967D2;\n",
              "      height: 32px;\n",
              "      padding: 0 0 0 0;\n",
              "      width: 32px;\n",
              "    }\n",
              "\n",
              "    .colab-df-convert:hover {\n",
              "      background-color: #E2EBFA;\n",
              "      box-shadow: 0px 1px 2px rgba(60, 64, 67, 0.3), 0px 1px 3px 1px rgba(60, 64, 67, 0.15);\n",
              "      fill: #174EA6;\n",
              "    }\n",
              "\n",
              "    [theme=dark] .colab-df-convert {\n",
              "      background-color: #3B4455;\n",
              "      fill: #D2E3FC;\n",
              "    }\n",
              "\n",
              "    [theme=dark] .colab-df-convert:hover {\n",
              "      background-color: #434B5C;\n",
              "      box-shadow: 0px 1px 3px 1px rgba(0, 0, 0, 0.15);\n",
              "      filter: drop-shadow(0px 1px 2px rgba(0, 0, 0, 0.3));\n",
              "      fill: #FFFFFF;\n",
              "    }\n",
              "  </style>\n",
              "\n",
              "      <script>\n",
              "        const buttonEl =\n",
              "          document.querySelector('#df-0ea7bea3-9990-40cd-bef7-09457f51b922 button.colab-df-convert');\n",
              "        buttonEl.style.display =\n",
              "          google.colab.kernel.accessAllowed ? 'block' : 'none';\n",
              "\n",
              "        async function convertToInteractive(key) {\n",
              "          const element = document.querySelector('#df-0ea7bea3-9990-40cd-bef7-09457f51b922');\n",
              "          const dataTable =\n",
              "            await google.colab.kernel.invokeFunction('convertToInteractive',\n",
              "                                                     [key], {});\n",
              "          if (!dataTable) return;\n",
              "\n",
              "          const docLinkHtml = 'Like what you see? Visit the ' +\n",
              "            '<a target=\"_blank\" href=https://colab.research.google.com/notebooks/data_table.ipynb>data table notebook</a>'\n",
              "            + ' to learn more about interactive tables.';\n",
              "          element.innerHTML = '';\n",
              "          dataTable['output_type'] = 'display_data';\n",
              "          await google.colab.output.renderOutput(dataTable, element);\n",
              "          const docLink = document.createElement('div');\n",
              "          docLink.innerHTML = docLinkHtml;\n",
              "          element.appendChild(docLink);\n",
              "        }\n",
              "      </script>\n",
              "    </div>\n",
              "  </div>\n",
              "  "
            ]
          },
          "metadata": {},
          "execution_count": 3
        }
      ]
    },
    {
      "cell_type": "code",
      "source": [],
      "metadata": {
        "id": "egXUOqy3XH-T"
      },
      "execution_count": 3,
      "outputs": []
    },
    {
      "cell_type": "code",
      "source": [
        "stock_data[\"Close\"].pct_change()"
      ],
      "metadata": {
        "colab": {
          "base_uri": "https://localhost:8080/"
        },
        "id": "INpkxG5GFZ6s",
        "outputId": "4f969af3-d578-4979-b1a4-a5cbad8bfd7a"
      },
      "execution_count": 4,
      "outputs": [
        {
          "output_type": "execute_result",
          "data": {
            "text/plain": [
              "Date\n",
              "2014-09-19         NaN\n",
              "2014-09-22   -0.042603\n",
              "2014-09-23   -0.030259\n",
              "2014-09-24    0.039004\n",
              "2014-09-25   -0.018218\n",
              "                ...   \n",
              "2022-09-12    0.027675\n",
              "2022-09-13   -0.055127\n",
              "2022-09-14   -0.006147\n",
              "2022-09-15   -0.001012\n",
              "2022-09-16   -0.027018\n",
              "Name: Close, Length: 2013, dtype: float64"
            ]
          },
          "metadata": {},
          "execution_count": 4
        }
      ]
    },
    {
      "cell_type": "code",
      "source": [
        "scaled_data"
      ],
      "metadata": {
        "colab": {
          "base_uri": "https://localhost:8080/"
        },
        "id": "ffcXeSwSLhRe",
        "outputId": "e83ea6b5-3851-46ca-b592-fc67d91d47a0"
      },
      "execution_count": 5,
      "outputs": [
        {
          "output_type": "execute_result",
          "data": {
            "text/plain": [
              "array([[-0.04260305],\n",
              "       [-0.03025922],\n",
              "       [ 0.03900426],\n",
              "       ...,\n",
              "       [-0.00614735],\n",
              "       [-0.0010121 ],\n",
              "       [-0.02701792]])"
            ]
          },
          "metadata": {},
          "execution_count": 5
        }
      ]
    },
    {
      "cell_type": "markdown",
      "source": [
        "# 2.) Create your x_train/y_train data so that your RNN uses percentage change data to make a binary forecast where the stock moves up or down the next day\n",
        "# Build an RNN Architecture accordingly"
      ],
      "metadata": {
        "id": "foHoGy9hq3_o"
      }
    },
    {
      "cell_type": "code",
      "source": [
        "x_train = []\n",
        "y_train = []\n",
        "\n",
        "#############################################################\n",
        "####Pick your input size and edit to make binary forecast####\n",
        "#############################################################\n",
        "input_size = 5\n",
        "for i in range(input_size,len(train_data)):\n",
        "  x_train.append(train_data[i-input_size:i,0])\n",
        "  y_train.append(1 if train_data[i,0]>0 else 0)\n",
        "  \n",
        "\n",
        "x_train, y_train = np.array(x_train), np.array(y_train)\n",
        "x_train = np.reshape(x_train, (x_train.shape[0], x_train.shape[1], 1))\n"
      ],
      "metadata": {
        "id": "5qGFB5HfqcVd"
      },
      "execution_count": 6,
      "outputs": []
    },
    {
      "cell_type": "code",
      "source": [
        "###################################\n",
        "####Build Your RNN Architecture####\n",
        "###################################\n",
        "model = Sequential()\n",
        "model.add(LSTM(50, return_sequences=True, input_shape=(x_train.shape[1], 1)))\n",
        "model.add(Dropout(0.2))\n",
        "model.add(LSTM(50, return_sequences=True))\n",
        "model.add(Dropout(0.2))\n",
        "model.add(LSTM(50))\n",
        "model.add(Dropout(0.2))\n",
        "model.add(Dense(1, activation='sigmoid'))\n",
        "\n",
        "model.compile(optimizer='adam', loss='mean_squared_error')\n",
        "model.fit(x_train, y_train, batch_size=1, epochs=3)"
      ],
      "metadata": {
        "colab": {
          "base_uri": "https://localhost:8080/"
        },
        "id": "kL8oHq7jEAIy",
        "outputId": "f8301836-72af-425e-da69-6f79b9081b8c"
      },
      "execution_count": 7,
      "outputs": [
        {
          "output_type": "stream",
          "name": "stdout",
          "text": [
            "Epoch 1/3\n",
            "1604/1604 [==============================] - 29s 12ms/step - loss: 0.2506\n",
            "Epoch 2/3\n",
            "1604/1604 [==============================] - 13s 8ms/step - loss: 0.2504\n",
            "Epoch 3/3\n",
            "1604/1604 [==============================] - 13s 8ms/step - loss: 0.2502\n"
          ]
        },
        {
          "output_type": "execute_result",
          "data": {
            "text/plain": [
              "<keras.callbacks.History at 0x7f32e42b2640>"
            ]
          },
          "metadata": {},
          "execution_count": 7
        }
      ]
    },
    {
      "cell_type": "code",
      "source": [
        "x_train.shape"
      ],
      "metadata": {
        "id": "p3BlSFA8Na77",
        "colab": {
          "base_uri": "https://localhost:8080/"
        },
        "outputId": "38efe799-42ae-4b0f-ce17-ac5af553bea5"
      },
      "execution_count": 8,
      "outputs": [
        {
          "output_type": "execute_result",
          "data": {
            "text/plain": [
              "(1604, 5, 1)"
            ]
          },
          "metadata": {},
          "execution_count": 8
        }
      ]
    },
    {
      "cell_type": "code",
      "source": [
        "y_train"
      ],
      "metadata": {
        "colab": {
          "base_uri": "https://localhost:8080/"
        },
        "id": "X2bsJnjd0_DA",
        "outputId": "9b6e997c-f687-4168-abb2-ceacec4f07ea"
      },
      "execution_count": 9,
      "outputs": [
        {
          "output_type": "execute_result",
          "data": {
            "text/plain": [
              "array([0, 1, 0, ..., 0, 1, 1])"
            ]
          },
          "metadata": {},
          "execution_count": 9
        }
      ]
    },
    {
      "cell_type": "markdown",
      "source": [
        "# 3.) Test your model and compare insample Accurracy, insample random walk assumption Accuracy, Out of sample Accuracy and out of sample random walk assumption Accuracy using a bar chart"
      ],
      "metadata": {
        "id": "yFhO9vMjsWPk"
      }
    },
    {
      "cell_type": "code",
      "source": [
        "test_data = scaled_data[training_data_len - input_size:, :]\n",
        "\n",
        "x_test = []\n",
        "for i in range(input_size, len(test_data)):\n",
        "    x_test.append(test_data[i-input_size:i, 0])\n",
        "\n",
        "x_test = np.array(x_test)\n",
        "x_test = np.reshape(x_test, (x_test.shape[0], x_test.shape[1], 1))\n",
        "\n",
        "predictions = model.predict(x_test)\n",
        "test_start_price = stock_data[\"Close\"][training_data_len+input_size-1]\n",
        "test_end_price = stock_data[\"Close\"][-1]\n",
        "\n",
        "# Calculate the price movement over the test data period\n",
        "price_movement = test_end_price - test_start_price\n",
        "\n",
        "# Set binary values for y_test based on price movement and test_predictions\n",
        "y_test = np.zeros_like(predictions)\n",
        "if price_movement > 0:\n",
        "    y_test[predictions.flatten() > 0.5] = 1\n",
        "elif price_movement < 0:\n",
        "    y_test[predictions.flatten() < 0.5] = 1"
      ],
      "metadata": {
        "id": "r1Xj6Ji-rwnM",
        "colab": {
          "base_uri": "https://localhost:8080/"
        },
        "outputId": "2031470d-2a0d-477c-b1a5-e429aecf3798"
      },
      "execution_count": 30,
      "outputs": [
        {
          "output_type": "stream",
          "name": "stdout",
          "text": [
            "13/13 [==============================] - 0s 7ms/step\n"
          ]
        }
      ]
    },
    {
      "cell_type": "code",
      "source": [
        "train_predictions = model.predict(x_train)\n",
        "train_predictions = np.round(train_predictions)\n",
        "train_accuracy = np.mean(train_predictions == y_train) * 100\n",
        "print(\"In-sample accuracy:\", train_accuracy)\n",
        "\n",
        "test_predictions = model.predict(x_test)\n",
        "test_predictions = np.round(test_predictions)\n",
        "test_accuracy = np.mean(test_predictions == y_test) * 100\n",
        "print(\"Out-of-sample accuracy:\", test_accuracy)\n",
        "\n",
        "train_rw_predictions = np.zeros_like(y_train)\n",
        "train_rw_predictions[1:] = y_train[:-1]\n",
        "train_rw_accuracy = np.mean(train_rw_predictions == y_train) * 100\n",
        "print(\"In-sample random walk assumption accuracy:\", train_rw_accuracy)\n",
        "\n",
        "test_rw_predictions = np.zeros_like(y_test)\n",
        "test_rw_predictions[1:] = y_test[:-1]\n",
        "test_rw_accuracy = np.mean(test_rw_predictions == y_test) * 100\n",
        "print(\"Out-of-sample random walk assumption accuracy:\", test_rw_accuracy)"
      ],
      "metadata": {
        "id": "Mvo2INihZMhk",
        "colab": {
          "base_uri": "https://localhost:8080/"
        },
        "outputId": "07f74bbe-b187-4442-d10f-d1ebe57f1f5f"
      },
      "execution_count": 31,
      "outputs": [
        {
          "output_type": "stream",
          "name": "stdout",
          "text": [
            "51/51 [==============================] - 0s 4ms/step\n",
            "In-sample accuracy: 51.6209476309227\n",
            "13/13 [==============================] - 0s 5ms/step\n",
            "Out-of-sample accuracy: 0.0\n",
            "In-sample random walk assumption accuracy: 50.31172069825436\n",
            "Out-of-sample random walk assumption accuracy: 100.0\n"
          ]
        }
      ]
    },
    {
      "cell_type": "code",
      "source": [
        "test_predictions.shape"
      ],
      "metadata": {
        "id": "ZP_GJ8X-Wkln",
        "colab": {
          "base_uri": "https://localhost:8080/"
        },
        "outputId": "71b73b29-aea3-4360-a290-6df2e3046467"
      },
      "execution_count": 21,
      "outputs": [
        {
          "output_type": "execute_result",
          "data": {
            "text/plain": [
              "(403, 1)"
            ]
          },
          "metadata": {},
          "execution_count": 21
        }
      ]
    },
    {
      "cell_type": "code",
      "source": [
        "import matplotlib.pyplot as plt\n",
        "\n",
        "accuracies = [train_accuracy, test_accuracy, train_rw_accuracy, test_rw_accuracy]\n",
        "labels = [\"In-sample accuracy\", \"Out-of-sample accuracy\",\"In-sample random walk assumption accuracy\",\"Out-of-sample random walk assumption accuracy\"]\n",
        "\n",
        "plt.figure(figsize=(18,10))\n",
        "plt.bar(labels, accuracies)\n",
        "plt.ylim(0, 100)\n",
        "plt.ylabel(\"Accuracy (%)\")\n",
        "plt.show()"
      ],
      "metadata": {
        "colab": {
          "base_uri": "https://localhost:8080/",
          "height": 429
        },
        "id": "eqJQ-r2c6jmD",
        "outputId": "5c0d28af-a0db-49e7-928a-13b06b751a18"
      },
      "execution_count": 32,
      "outputs": [
        {
          "output_type": "display_data",
          "data": {
            "text/plain": [
              "<Figure size 1296x720 with 1 Axes>"
            ],
            "image/png": "iVBORw0KGgoAAAANSUhEUgAABCIAAAJDCAYAAADeqbWWAAAAOXRFWHRTb2Z0d2FyZQBNYXRwbG90bGliIHZlcnNpb24zLjUuMywgaHR0cHM6Ly9tYXRwbG90bGliLm9yZy/NK7nSAAAACXBIWXMAAAsTAAALEwEAmpwYAAAtGElEQVR4nO3debgsZX0n8O9PEBFURCAEwQgqSnDXG8ck6kPAzOi4YCJuMYrGEbe4xXUySVyyaUzGPRrcQKNGRYlEMxpECAYVuYgsogbEa0RRr4kb7so7f1QdbnM459w+ePvtS/P5PM95TlV1dfWvuuutqv7W0tVaCwAAAEAP15p3AQAAAMA1hyACAAAA6EYQAQAAAHQjiAAAAAC6EUQAAAAA3QgiAAAAgG5mFkRU1Rur6utVdd7EsBtV1YlVdcH4f/dxeFXVK6rqwqo6p6ruNKu6AAAAgPmZ5RkRxyS517Jhz01yUmvtwCQnjf1Jcu8kB45/RyV5zQzrAgAAAOZkZkFEa+3UJP+1bPDhSY4du49N8oCJ4W9ug48nuWFV7TOr2gAAAID56H2PiL1ba5eM3V9NsvfYvW+SL02Md/E4DAAAAFggO87rhVtrraraep9XVUdluHwju+66650POuigbV4bAACwfTn3y9+edwkwN7fdd7d5l7BuZ5555jdaa3ut9FjvIOJrVbVPa+2S8dKLr4/Dv5zkJhPj7TcOu5LW2tFJjk6SDRs2tI0bN86yXgAAYDuw/3PfP+8SYG42vug+8y5h3arqi6s91vvSjBOSHDl2H5nkvRPDHzn+esZdk3x74hIOAAAAYEHM7IyIqnp7kkOS7FlVFyd5XpIXJXlnVT0myReTPHgc/Z+T/M8kFyb5fpJHz6ouAAAAYH5mFkS01h62ykOHrTBuS/KkWdUCAAAAbB96X5oBAAAAXIMJIgAAAIBuBBEAAABAN4IIAAAAoBtBBAAAANCNIAIAAADoRhABAAAAdCOIAAAAALoRRAAAAADdCCIAAACAbgQRAAAAQDeCCAAAAKAbQQQAAADQjSACAAAA6EYQAQAAAHQjiAAAAAC6EUQAAAAA3QgiAAAAgG4EEQAAAEA3gggAAACgG0EEAAAA0I0gAgAAAOhGEAEAAAB0I4gAAAAAuhFEAAAAAN0IIgAAAIBuBBEAAABAN4IIAAAAoBtBBAAAANCNIAIAAADoRhABAAAAdCOIAAAAALoRRAAAAADdCCIAAACAbgQRAAAAQDeCCAAAAKAbQQQAAADQjSACAAAA6EYQAQAAAHQjiAAAAAC6EUQAAAAA3QgiAAAAgG4EEQAAAEA3gggAAACgG0EEAAAA0I0gAgAAAOhGEAEAAAB0I4gAAAAAuhFEAAAAAN0IIgAAAIBuBBEAAABAN4IIAAAAoBtBBAAAANCNIAIAAADoRhABAAAAdCOIAAAAALoRRAAAAADdCCIAAACAbgQRAAAAQDeCCAAAAKAbQQQAAADQjSACAAAA6EYQAQAAAHQjiAAAAAC6EUQAAAAA3QgiAAAAgG4EEQAAAEA3gggAAACgG0EEAAAA0I0gAgAAAOhGEAEAAAB0I4gAAAAAuhFEAAAAAN0IIgAAAIBuBBEAAABAN4IIAAAAoBtBBAAAANCNIAIAAADoRhABAAAAdCOIAAAAALoRRAAAAADdCCIAAACAbgQRAAAAQDeCCAAAAKAbQQQAAADQjSACAAAA6EYQAQAAAHQjiAAAAAC6EUQAAAAA3QgiAAAAgG4EEQAAAEA3gggAAACgG0EEAAAA0I0gAgAAAOhGEAEAAAB0I4gAAAAAuhFEAAAAAN0IIgAAAIBuBBEAAABAN4IIAAAAoJu5BBFV9fSq+nRVnVdVb6+qnavqgKo6vaourKp3VNVO86gNAAAAmJ3uQURV7ZvkKUk2tNZuk2SHJA9N8uIkL22t3SLJN5M8pndtAAAAwGzN69KMHZNct6p2TLJLkkuSHJrkuPHxY5M8YD6lAQAAALPSPYhorX05yV8n+Y8MAcS3k5yZ5FuttZ+Oo12cZN/etQEAAACzNY9LM3ZPcniSA5LcOMmuSe61jucfVVUbq2rj5s2bZ1QlAAAAMAvzuDTjnkm+0Frb3Fr7SZL3JPn1JDccL9VIkv2SfHmlJ7fWjm6tbWitbdhrr736VAwAAABsE/MIIv4jyV2rapeqqiSHJTk/yclJjhjHOTLJe+dQGwAAADBD87hHxOkZbkr5ySTnjjUcneQ5Sf6gqi5MskeSN/SuDQAAAJitHbc+yrbXWntekuctG3xRkrvMoRwAAACgk3n9fCcAAABwDSSIAAAAALoRRAAAAADdCCIAAACAbgQRAAAAQDeCCAAAAKAbQQQAAADQjSACAAAA6EYQAQAAAHQjiAAAAAC6EUQAAAAA3QgiAAAAgG4EEQAAAEA3gggAAACgG0EEAAAA0I0gAgAAAOhGEAEAAAB0I4gAAAAAuhFEAAAAAN0IIgAAAIBuBBEAAABAN4IIAAAAoBtBBAAAANCNIAIAAADoRhABAAAAdCOIAAAAALoRRAAAAADdCCIAAACAbgQRAAAAQDeCCAAAAKAbQQQAAADQjSACAAAA6EYQAQAAAHQjiAAAAAC6EUQAAAAA3QgiAAAAgG4EEQAAAEA3gggAAACgG0EEAAAA0I0gAgAAAOhGEAEAAAB0I4gAAAAAuhFEAAAAAN0IIgAAAIBuBBEAAABAN4IIAAAAoBtBBAAAANCNIAIAAADoRhABAAAAdCOIAAAAALoRRAAAAADdCCIAAACAbgQRAAAAQDeCCAAAAKAbQQQAAADQjSACAAAA6EYQAQAAAHQjiAAAAAC6EUQAAAAA3QgiAAAAgG4EEQAAAEA3gggAAACgG0EEAAAA0I0gAgAAAOhGEAEAAAB0I4gAAAAAuhFEAAAAAN0IIgAAAIBuBBEAAABAN4IIAAAAoBtBBAAAANCNIAIAAADoRhABAAAAdCOIAAAAALoRRAAAAADdCCIAAACAbgQRAAAAQDeCCAAAAKAbQQQAAADQjSACAAAA6EYQAQAAAHQjiAAAAAC6EUQAAAAA3QgiAAAAgG4EEQAAAEA3gggAAACgG0EEAAAA0I0gAgAAAOhGEAEAAAB0I4gAAAAAuhFEAAAAAN0IIgAAAIBuBBEAAABAN4IIAAAAoBtBBAAAANCNIAIAAADoRhABAAAAdCOIAAAAALoRRAAAAADdCCIAAACAbuYSRFTVDavquKr6bFV9pqp+tapuVFUnVtUF4//d51EbAAAAMDvzOiPi5Uk+0Fo7KMntk3wmyXOTnNRaOzDJSWM/AAAAsEC6BxFVtVuSeyR5Q5K01n7cWvtWksOTHDuOdmySB/SuDQAAAJiteZwRcUCSzUneVFVnVdXrq2rXJHu31i4Zx/lqkr3nUBsAAAAwQ/MIInZMcqckr2mt3THJ97LsMozWWkvSVnpyVR1VVRurauPmzZtnXiwAAACw7cwjiLg4ycWttdPH/uMyBBNfq6p9kmT8//WVntxaO7q1tqG1tmGvvfbqUjAAAACwbXQPIlprX03ypaq61TjosCTnJzkhyZHjsCOTvLd3bQAAAMBs7Tin131ykrdW1U5JLkry6AyhyDur6jFJvpjkwXOqDQAAAJiRuQQRrbVPJdmwwkOHdS4FAAAA6Gge94gAAAAArqEEEQAAAEA3gggAAACgG0EEAAAA0I0gAgAAAOhGEAEAAAB0I4gAAAAAuhFEAAAAAN0IIgAAAIBuBBEAAABAN4IIAAAAoBtBBAAAANCNIAIAAADoRhABAAAAdCOIAAAAALoRRAAAAADdCCIAAACAbnacZqSq2j3JjZP8IMmm1tplM60KAAAAWEirBhFVtVuSJyV5WJKdkmxOsnOSvavq40n+trV2cpcqAQAAgIWw1hkRxyV5c5K7t9a+NflAVd05ySOq6mattTfMsD4AAABggawaRLTWfnONx85McuZMKgIAAAAW1lT3iEiSqtoryVOTXDfJa1trF8ysKgAAAGAhredXM/4myQeTHJ/kbbMpBwAAAFhkqwYRVfXBqrrHxKCdkmwa/64z27IAAACARbTWGREPTnK/qnp7Vd08yR8n+cskL0/yxB7FAQAAAItlrZtVfjvJs6rqZkn+PMlXkvz+8l/QAAAAAJjWqkHEeBbEE5L8OMkzktw8yTuq6v1JXt1a+1mfEgEAAIBFsdalGW9P8p4kJyd5S2vtI621/5HkW0n+pUNtAAAAwIJZ6+c7r5PkC0mul2SXpYGttTdX1btmXRgAAACweNYKIp6Y5FUZLs14/OQDrbUfzLIoAAAAYDGtdbPK05Kc1rEWAAAAYMGteo+IqvqnqrpvVV17hcduVlUvrKrfm215AAAAwCJZ69KMxyb5gyQvr6r/SrI5yc5J9k/y+SSvaq29d+YVAgAAAAtjrUszvprk2UmeXVX7J9knyQ+S/Htr7ft9ygMAAAAWyVpnRFyutbYpyaaZVgIAAAAsvFXvEQEAAACwrQkiAAAAgG62GkRU1f2qSmABAAAA/NymCRgekuSCqvqrqjpo1gUBAAAAi2urQURr7XeT3DHDT3YeU1Ufq6qjqur6M68OAAAAWCjT/mrGd6rquCTXTfK0JL+V5FlV9YrW2itnWN9C2v+57593CTA3m150n3mXAAAAzNE094i4f1Udn+SUJNdOcpfW2r2T3D7JM2ZbHgAAALBIpjkj4oFJXtpaO3VyYGvt+1X1mNmUBQAAACyiaYKI5ye5ZKmnqq6bZO/W2qbW2kmzKgwAAABYPNP8asa7klw20f+zcRgAAADAukwTROzYWvvxUs/YvdPsSgIAAAAW1TRBxOaquv9ST1UdnuQbsysJAAAAWFTT3CPi8UneWlWvSlJJvpTkkTOtCgBgG/Pz2VzT+QltYHux1SCitfb5JHetquuN/ZfOvCoAAABgIU1zRkSq6j5Jbp1k56pKkrTWXjjDugAAAIAFtNV7RFTVa5M8JMmTM1ya8aAkN51xXQAAAMACmuZmlb/WWntkkm+21l6Q5FeT3HK2ZQEAAACLaJog4ofj/+9X1Y2T/CTJPrMrCQAAAFhU09wj4p+q6oZJXpLkk0laktfNsigAAABgMa0ZRFTVtZKc1Fr7VpJ3V9X7kuzcWvt2j+IAAACAxbLmpRmttcuSvHqi/0dCCAAAAOCqmuYeESdV1QNr6Xc7AQAAAK6iaYKIxyV5V5IfVdV3quq7VfWdGdcFAAAALKCt3qyytXb9HoUAAAAAi2+rQURV3WOl4a21U7d9OQAAAMAim+bnO5810b1zkrskOTPJoTOpCAAAAFhY01yacb/J/qq6SZKXzaogAAAAYHFNc7PK5S5O8svbuhAAAABg8U1zj4hXJmlj77WS3CHJJ2dYEwAAALCgprlHxMaJ7p8meXtr7bQZ1QMAAAAssGmCiOOS/LC19rMkqaodqmqX1tr3Z1saAAAAsGimuUfESUmuO9F/3SQfmk05AAAAwCKbJojYubV26VLP2L3L7EoCAAAAFtU0QcT3qupOSz1VdeckP5hdSQAAAMCimuYeEU9L8q6q+kqSSvKLSR4yy6IAAACAxbTVIKK1dkZVHZTkVuOgz7XWfjLbsgAAAIBFtNVLM6rqSUl2ba2d11o7L8n1quqJsy8NAAAAWDTT3CPisa21by31tNa+meSxM6sIAAAAWFjTBBE7VFUt9VTVDkl2ml1JAAAAwKKa5maVH0jyjqr6u7H/ceMwAAAAgHWZJoh4TpKjkjxh7D8xyetmVhEAAACwsLZ6aUZr7bLW2mtba0e01o5Icn6SV86+NAAAAGDRTHNGRKrqjkkeluTBSb6Q5D2zLAoAAABYTKsGEVV1ywzhw8OSfCPJO5JUa+03OtUGAAAALJi1zoj4bJKPJLlva+3CJKmqp3epCgAAAFhIa90j4reTXJLk5Kp6XVUdlqTWGB8AAABgTasGEa21f2ytPTTJQUlOTvK0JL9QVa+pqv/eqT4AAABggUzzqxnfa629rbV2vyT7JTkrw096AgAAAKzLVoOISa21b7bWjm6tHTarggAAAIDFta4gAgAAAODnIYgAAAAAuhFEAAAAAN0IIgAAAIBuBBEAAABAN4IIAAAAoBtBBAAAANCNIAIAAADoRhABAAAAdCOIAAAAALoRRAAAAADdCCIAAACAbgQRAAAAQDeCCAAAAKAbQQQAAADQzdyCiKraoarOqqr3jf0HVNXpVXVhVb2jqnaaV20AAADAbMzzjIinJvnMRP+Lk7y0tXaLJN9M8pi5VAUAAADMzFyCiKraL8l9krx+7K8khyY5bhzl2CQPmEdtAAAAwOzM64yIlyV5dpLLxv49knyrtfbTsf/iJPvOoS4AAABghroHEVV13yRfb62deRWff1RVbayqjZs3b97G1QEAAACzNI8zIn49yf2ralOSf8hwScbLk9ywqnYcx9kvyZdXenJr7ejW2obW2oa99tqrR70AAADANtI9iGit/e/W2n6ttf2TPDTJh1trD09ycpIjxtGOTPLe3rUBAAAAszXPX81Y7jlJ/qCqLsxwz4g3zLkeAAAAYBvbceujzE5r7ZQkp4zdFyW5yzzrAQAAAGZrezojAgAAAFhwgggAAACgG0EEAAAA0I0gAgAAAOhGEAEAAAB0I4gAAAAAuhFEAAAAAN0IIgAAAIBuBBEAAABAN4IIAAAAoBtBBAAAANCNIAIAAADoRhABAAAAdCOIAAAAALoRRAAAAADdCCIAAACAbgQRAAAAQDeCCAAAAKAbQQQAAADQjSACAAAA6EYQAQAAAHQjiAAAAAC6EUQAAAAA3QgiAAAAgG4EEQAAAEA3gggAAACgG0EEAAAA0I0gAgAAAOhGEAEAAAB0I4gAAAAAuhFEAAAAAN0IIgAAAIBuBBEAAABAN4IIAAAAoBtBBAAAANCNIAIAAADoRhABAAAAdCOIAAAAALoRRAAAAADdCCIAAACAbgQRAAAAQDeCCAAAAKAbQQQAAADQjSACAAAA6EYQAQAAAHQjiAAAAAC6EUQAAAAA3QgiAAAAgG4EEQAAAEA3gggAAACgG0EEAAAA0I0gAgAAAOhGEAEAAAB0I4gAAAAAuhFEAAAAAN0IIgAAAIBuBBEAAABAN4IIAAAAoBtBBAAAANCNIAIAAADoRhABAAAAdCOIAAAAALoRRAAAAADdCCIAAACAbgQRAAAAQDeCCAAAAKAbQQQAAADQjSACAAAA6EYQAQAAAHQjiAAAAAC6EUQAAAAA3QgiAAAAgG4EEQAAAEA3gggAAACgG0EEAAAA0I0gAgAAAOhGEAEAAAB0I4gAAAAAuhFEAAAAAN0IIgAAAIBuBBEAAABAN4IIAAAAoBtBBAAAANCNIAIAAADoRhABAAAAdCOIAAAAALoRRAAAAADdCCIAAACAbgQRAAAAQDeCCAAAAKAbQQQAAADQjSACAAAA6EYQAQAAAHQjiAAAAAC6EUQAAAAA3QgiAAAAgG4EEQAAAEA3gggAAACgG0EEAAAA0I0gAgAAAOimexBRVTepqpOr6vyq+nRVPXUcfqOqOrGqLhj/7967NgAAAGC25nFGxE+TPKO1dnCSuyZ5UlUdnOS5SU5qrR2Y5KSxHwAAAFgg3YOI1tolrbVPjt3fTfKZJPsmOTzJseNoxyZ5QO/aAAAAgNma6z0iqmr/JHdMcnqSvVtrl4wPfTXJ3vOqCwAAAJiNuQURVXW9JO9O8rTW2ncmH2uttSRtlecdVVUbq2rj5s2bO1QKAAAAbCtzCSKq6toZQoi3ttbeMw7+WlXtMz6+T5Kvr/Tc1trRrbUNrbUNe+21V5+CAQAAgG1iHr+aUUnekOQzrbX/O/HQCUmOHLuPTPLe3rUBAAAAs7XjHF7z15M8Ism5VfWpcdgfJnlRkndW1WOSfDHJg+dQGwAAADBD3YOI1tq/JalVHj6sZy0AAABAX3P91QwAAADgmkUQAQAAAHQjiAAAAAC6EUQAAAAA3QgiAAAAgG4EEQAAAEA3gggAAACgG0EEAAAA0I0gAgAAAOhGEAEAAAB0I4gAAAAAuhFEAAAAAN0IIgAAAIBuBBEAAABAN4IIAAAAoBtBBAAAANCNIAIAAADoRhABAAAAdCOIAAAAALoRRAAAAADdCCIAAACAbgQRAAAAQDeCCAAAAKAbQQQAAADQjSACAAAA6EYQAQAAAHQjiAAAAAC6EUQAAAAA3QgiAAAAgG4EEQAAAEA3gggAAACgG0EEAAAA0I0gAgAAAOhGEAEAAAB0I4gAAAAAuhFEAAAAAN0IIgAAAIBuBBEAAABAN4IIAAAAoBtBBAAAANCNIAIAAADoRhABAAAAdCOIAAAAALoRRAAAAADdCCIAAACAbgQRAAAAQDeCCAAAAKAbQQQAAADQjSACAAAA6EYQAQAAAHQjiAAAAAC6EUQAAAAA3QgiAAAAgG4EEQAAAEA3gggAAACgG0EEAAAA0I0gAgAAAOhGEAEAAAB0I4gAAAAAuhFEAAAAAN0IIgAAAIBuBBEAAABAN4IIAAAAoBtBBAAAANCNIAIAAADoRhABAAAAdCOIAAAAALoRRAAAAADdCCIAAACAbgQRAAAAQDeCCAAAAKAbQQQAAADQjSACAAAA6EYQAQAAAHQjiAAAAAC6EUQAAAAA3QgiAAAAgG4EEQAAAEA3gggAAACgG0EEAAAA0I0gAgAAAOhGEAEAAAB0I4gAAAAAuhFEAAAAAN0IIgAAAIBuBBEAAABAN4IIAAAAoBtBBAAAANCNIAIAAADoRhABAAAAdCOIAAAAALoRRAAAAADdCCIAAACAbgQRAAAAQDeCCAAAAKAbQQQAAADQjSACAAAA6EYQAQAAAHQjiAAAAAC6EUQAAAAA3WxXQURV3auqPldVF1bVc+ddDwAAALBtbTdBRFXtkOTVSe6d5OAkD6uqg+dbFQAAALAtbTdBRJK7JLmwtXZRa+3HSf4hyeFzrgkAAADYhranIGLfJF+a6L94HAYAAAAsiB3nXcB6VdVRSY4aey+tqs/Nsx6ulvZM8o15F3FNVS+edwVczWm/cPWl/c6ZbTA/J214jq6m7femqz2wPQURX05yk4n+/cZhV9BaOzrJ0b2KYvFU1cbW2oZ51wGsn/YLV1/aL1y9acNsS9vTpRlnJDmwqg6oqp2SPDTJCXOuCQAAANiGtpszIlprP62q30/ywSQ7JHlja+3Tcy4LAAAA2Ia2myAiSVpr/5zkn+ddBwvPpT1w9aX9wtWX9gtXb9ow20y11uZdAwAAAHANsT3dIwIAAABYcIII1q2qLp13DWupqk1Vtee864Ceqmq/qnpvVV1QVZ+vqpePN/7d2vP+8Cq+3tur6pyqevpVef62UFWHVNX75vX69Gf7s9XXP6aqjpjX6y9XVadU1Yaxe7v+7NZSVftX1e9M9G+oqlfMs6btie3P3GrYbtrU2EbOG7sfVVWvmndNV1VVPaCqDp7of2FV3XOeNS0qQQR0UlXb1T1ZWBxVVUnek+QfW2sHJrllkusl+fMpnr7uHcGq+sUkv9Jau11r7aXrff41gfbOelXVDvOugVXtn+TyIKK1trG19pT5lbN+s1on2f6sn+3Ddu8BSS4PIlprf9Ja+9D8ylm/q8v2RBDBVTamwadU1XFV9dmqeuu4QVo+3j5VdWpVfaqqzququ4/DX1NVG6vq01X1gonxN1XVX47jb6yqO1XVB8eU/fETr31qVb2/qj5XVa+tqistz1X1u1X1iXFaf7dSw6yqP6mqM8bajl6ah6q6RVV9qKrOrqpPVtXNx+HPqapzx+EvGodNHvXZs6o2jd2PqqoTqurDSU6qqutV1Unj9M6tqsMn6njkmPCfXVVvqarrV9UXqura4+M3mOyHCYcm+WFr7U1J0lr7WZKnJ/m9qtpl+dGJqnrf2IZelOS6Y/t46/KJVtXOVfWmcVk9q6p+Y3zoX5LsOz7v7sue86CxLZ1dVaeOw/avqo+My/0nq+rXxuGHVNW/1nAk7aKqelFVPXxss+dOtLljxja+sar+varuu0Ktu1bVG8fnnjXZtibGmbr9jcP2rqrjx2FnV9Wv1cRRn3GcZ1bV88fuU6rqZVW1MclTq+p+VXX6WM+HqmrviTqW3tdzquqBVfV7VfWyiek+tqquljvZPdTibH82VdWLq+qTSR40fu5njMvbu6tql3G8Y6rqFVX10bGtHDEOr6p61VjHh5L8wsS0DxuXvXPHtnGdaedxWY3PqqqnjN0vrWF7lqo6tMb1xmrv5yqf3Z5V9bGqus8Kj/1jVZ05TueocdgO4/yfN87L08fhT6mq88c29A/jsOdX1TMnpnfe2Gb3H5eTY2pYh7y1qu5ZVafVcBT/LhPPf8tY3wVV9dhxUi9KcvfxPXt6TRwNr6objXWfU1Ufr6rbTUzrjeNyetHSe7jCPK+2LP7K+HmfPS5H1x/fi78e5+ucqnryxGe659i9oapOWTY/pyV5S62yLh7HvcK+TVXdfFwulx4/cLJ/gu3PdNufQ8Y6Tkhy/jjsSsv7OPzSqvrzcT4+Xlu2HQeMy+a5VfVnE+NXVb2ktrSRh6xnHpfVeW5V3XCc5n9W1SPH4W+uqt9caxlaSVXdZ6x5z2XD7zIOP6uG5fxW4/Bb15b15jnjcrdrDevbs8d5XJq/tZb7Y8c6v1hVv11VfzXO2wdqy371ponhn6hhv//Xktw/yUvGGm5eE2ea1drr1RfUlv2Lg1Z4L6Zuf+OwK30PqWVn4tSw/n/URA3TbE9W2rd5YVU9bWK6f15VT13rs90mWmv+/K3rL8ml4/9Dknw7yX4ZQq2PJbnbCuM/I8n/Gbt3SHL9sftGE8NOSXK7sX9TkieM3S9Nck6S6yfZK8nXJl77h0luNj7/xCRHTDx/zyS/nOSfklx7HP63SR65Qn03muh+S5L7jd2nJ/mtsXvnJLskuXeSjybZZdk8nJJkw9i9Z5JNY/ejklw8Md6OSW4wMd6FSSrJrZP8e5I9l033TUkeMHYfleRv5v35+9v+/pI8JclLVxh+VpLbjcvhqyaGvy/JIWP3pWtM9xkZfko5SQ5K8h9jW9g/yXmrPOfcJPuO3Tcc/++SZOex+8AkG8fuQ5J8K8k+Sa6T5MtJXjA+9tQkLxu7j0nygQzrmQPHNrXz+Pz3jeP8RZLfXXrdsT3tuqy29ba/dyR52ti9Q5Ldls97kmcmef7YfUqSv514bPfk8ptC/6+l9pvkxUvzNjHe9ZJ8PlvWVx9Nctt5L1vb218Wb/uzKcmzJ/r3mOj+syRPnmgD7xrn9eAkF47Df3t8/R2S3DhDezoiQ/v4UpJbjuO9eWJZ3uo8LqvxrkneNXZ/JMknklw7yfOSPG4r7+cp2bJtvDTJ3hm2rb+5yue7NJ3rJjkvyR5J7pzkxIlxltYrX0lynWXDnp/kmRPjnpehze6f5KdJbju+h2cmeWOG9n94hqP5S88/e3z9Pcf38MaZWNdMLANL655XJnne2H1okk9NTOujGdZteyb5z4zLwyrzfPl7l2SnJBdlOPKfJDfIsP56QpLjkuy47LmbsmX9tSHJKRM1nJnkumP/auvi1fZtTk5yh7H7LzIuj8vqt/2ZbvtzSJLvJTlgreV97G/Zsi/6V0n+aOw+IeN6JMmTsmV9+MBsWQ/sPb5X+0w7j8vqfG2S+yS5TZIzkrxuHH5Bkl3XeD8v/1yWPvMkv5VhnbH7Cq9zg2xZju+Z5N0T7enhY/dO43vzwKU6xuG7TbHc/1uG9dTtk3w/yb3Hx47Plv3qTdmyfXjkxOd5TMZ1+mR/tr5eXVpfPzHJ61eY5/W2v5W+hxySK66LXpXkURM1TLM9WW3f5pPjsGtl2B/ZY/k8bOs/Z0Tw8/pEa+3i1tplST6VYUFe7owkj67hqOFtW2vfHYc/eEztzsrwReDgieecMP4/N8nprbXvttY2J/lRVd1w4rUvakP6/vYkd1v2uodl2IE5o6o+NfbfbIX6fqOGo5bnZtiJuHVVXT/Dxuz4JGmt/bC19v0MK8s3jd1prf3X2m9PkmEHamm8SvIXVXVOkg8l2TfDRuPQDDt631g23dcnefTY/egMwQT0crckf58krbXPJvlihtNu13JakmNqOJK4dAT42kleN7axd+WKbf2M1tolrbUfZdjw/cs4/NxccX3yztbaZa21CzLsoC8/2vDfkzx3bOunZNho/9Kycdbb/g5N8ppx2M9aa9/eyrwnwwZ+yX5JPjjO97MyrOeSYT3y6qWRWmvfbK1dmuTDSe47Hkm5dmvt3Cle75psEbY/yRWXmduMR8zOTfLwbFlmkuHL8mWttfMzLLdJco8kbx+Xz69kWIaS5FZJvtBa+/ex/9hx3PXM45Izk9y5qm6Q5EcZQp8NSe6e4UtGsvb7ueTaSU7KsKN84irvxVOq6uwkH09ykww76xcluVlVvbKq7pXkO+O45yR5a1X9boaQYWu+0Fo7d1xePp3kpDbsdS9f17y3tfaDcX1wcpK7bGW6d8twECOttQ8n2WN8r5Lk/a21H43T+nq2fG6TVnrvbpXkktbaGeN0v9Na+2mGdcffjd3T7oOc0Fr7wdi92rp4tX2b12doPzskeUiSt03xetvKom1/kmG98YWJ/pWW9yT5cYbAJhna31Itv55hfZOMy9zobtmyHvhakn9N8ivrnMclH8mwrrhHhu3fbatq3yTfbK19L2u/n5MOTfKcJPdprX1zhcd3S/KuGs4wfGm2rOs+luQPq+o5SW46LrvnJvnN8Wj/3afcFv+/1tpPxufukCFMWmm+3z7x/1e3Ms2trVffM/6f/MwmTd3+1vgesjXTbE+utG/TWtuU5D+r6o4ZluezWmv/OcXr/VwEEfy8fjTR/bMkO1bVfxtPZ/pUVd2/tXZqhob65QwbiEdW1QEZjiQe1lq7XZL3Z1hxL5/uZcte47IMRwWSITGetLy/khzbWrvD+Her1trzrzBC1c4ZjlQd0Vq7bZLXLatjWj/Nlva0/Pnfm+h+eIajTndurd0hydfWer3W2mlJ9q+qQ5Ls0Fo7b7VxuUY7P8OXnsuNO8K/lOGo/+TymayyzFXVkyba7o2neeHx9L1PjTtgaa09PskfZdipOrOq9shwmu7XMhyZ2JDhKMeS5e17su1PXkc7TXt/4ER7/6XW2meWjbOu9reKrb2Xk+39lRmOBN42yeOmeK3XZziSJHScztV6+zNhcpk5Jsnvj8vMC1apa2n6P49p5jFJMu7MfyHDsvnRDF9UfiPJLZJ8Zor3c8lPM+yg/4+VChq3c/dM8quttdtn+GK+8/gl5vYZvuA9PkM7SYajtq9OcqcMgc+OWbt9bqt1zXpcaRmdfHAd793WTLsPsta6eCXvznC09r5Jzlzli4ntz3Tbn2Tis1hteR8f/skYkiVXXm7WuzxOO49LTs0QMt49Q5vbnOFsgKXQcdpl6PMZzrRaLTz60yQnt9Zuk+R+Gee9tfa2DJdG/CDJP1fVoeMX/ztlCBH+rKr+ZJzGWsv9j8bpXZYrvp9rfbY/T1u//DWzQlsfrbf9rWQ9+yDHZPXtyUom90HeeBVqWzdBBNtca+30iZXxCVV10wyne74uw0J+pwynZH0vybdruPbt3lfhpe5Sw/Vy18qQ1P/bssdPSnJEVf1Ccvl1nDddNs5So/xGVV0vw8o241Gzi6vqAeNzrzNeW3VihqMDS9dZ3Wh8/qZs2RCvdcfy3ZJ8vbX2kxqud1yq58MZrufaY9l0k+HUr7fFFxNWd1KSXWrLtZw7JPmbJMeMCfqmJHeoqmtV1U1yxSN8P6nxesnW2qsn2u5XMux4PHyc5i0z7Fh+bvKFW2v/Z+k543g3H9cBf5JhB+YmGZb7S8Ydgkdky5Gq9XjQWP/NMxxZ/tyyxz+Y5MlVl9/j5Y4rTGO97e+kDKdCL12nvluGnYhfqKo9arg29ErXCy97vS+P3UdODD8xw2m1Gae9ezKsOzO8X7+TLUdpWIer2fZnJddPcsnYJh8+xfinJnnIuHzukyEgSIb2sX9V3WLsf0SGo6RX1UcyfGE+dex+fIYjZi3Tv58tye8lOWg82rncbhmOun6/hrOC7poM95RIcq3W2rszfMm80/i+36S1dnKGo667Zbi8aVOGzzhVdackB1yFeT28hvsT7JHhNOgzknw3w2ezksn15CFJvtFa+84q4y632nv3uST7VNWvjNO9/hi0nJjkcWP3avsgD1zj9VZbF6+4b9Na+2GGdetrsvo+iO3PdNuf5VZc3rfitCQPHbsn1w8fyZb1wF4ZwtdPTDG9K2mtfSnDpUQHttYuyrBuW2r7S3VP835+McOy+OaquvUKj09uHx+1NLCqbpbkotbaK5K8N8ntxmDq+621v0/ykoxtPNMv92t5yMT/j43dq7X3n3e9OnX7W+N7yBeTHDz23zDD2XarWW17stK+TTJctnKvDGfTfHAd83WVCSLo4ZAkZ1fVWRka+stba2dnSH8/m+FL9mlXYbpnZLg26jMZjtYcP/lgG05f/aMk/1LDqdgnZrhObnKcb2U4C+K8DI3ujImHH5HhtLlzMhwF+sXW2gcynNK6cUzgl26K9ddJnjDO41o/3fbWJBtqOE3qkRnmP621T2e4w/S/1nCa3v9d9pzd44sJqxi/DPxWhp2lCzJcn/rDbLkj+WkZ2sj5SV6RZPKGY0cnOadWuFlYhrOFrjUur+/IcB3ij1YYb9JLarjh0nkZ2s3Z43SOHJftg3LFxH5a/5Fhx+r/JXn8uIM86U8znPZ4TlV9euxfbr3t76kZLt06N8OR3IPHo8MvHGs5cWkaq3h+hlNPz0zyjYnhf5Zk9xpvqpYtXx6T5J1JTmsrn8rK+h2S7XT7s4o/znBd8GlZe9lacnyGa7fPzxBaf2x8/R9mOKr1rnH5vSzDtd9X1Ucy1P+xNpz6/cNxWNbzfrbhUpaHJTm0qp647OEPZDir5TMZbg758XH4vklOGbe5f5/kf2fYgf/7cd7OSvKKcXv+7iQ3GtcBv59hXbhe52S4JOPjSf50/FJ8TpKf1XBjt+U/Gfn8DJeunDPWfWSmtNp711r7cYbl9ZXjOuLEDAdOXp9hXXjOOHzplzxekOTlNdwo92drvOSK6+I19m2SYb15Wbac0r98Hmx/ptv+LLfa8r6WpyZ50vie7Dsx/PgMy+jZGYL1Z7fWvjrF9FZzera0nY+Mr7UUtk79frbhkpqHZ1gP3XzZw3+V5C/HdfPk2QMPTnLeuBzeJsN67bZJPjEOe16GbWgy/XK/lt3HtvvUDGcsJMk/JHlWDTelvLzubbBeXW/7W+l7yJcy7CecN/4/a43XW217cqV9m7GOH2dY971zXFfP3NJNtOBqZTzq8MzW2lpHIxdCDXfqPby19oh51wLzUFXHZLg503HzrmXWargb9ktbayfNuxZWdk3a/lzT1HAvkUtba38971q2FzX8CslurbU/nnct83BN2v5c09TwC3cb2nh/qGu68UyzTyZ5UBvuhzJzfscWtmNV9coMp2r+z3nXAszOeIrlJ5KcLYQAtgdVdXySm2e4uR2woKrq4Aw3SD2+VwiROCMCAAAA6Mg9IgAAAIBuBBEAAABAN4IIAAAAoBtBBAAAANCNIAIAAADoRhABAAAAdPP/Abepb0qp4KxWAAAAAElFTkSuQmCC\n"
          },
          "metadata": {
            "needs_background": "light"
          }
        }
      ]
    },
    {
      "cell_type": "markdown",
      "source": [
        "DONOT# 4.) Plot in and out of sample accuracy"
      ],
      "metadata": {
        "id": "8bncNwh8tKiE"
      }
    },
    {
      "cell_type": "code",
      "source": [
        "import matplotlib.pyplot as plt\n",
        "\n",
        "# Make predictions on full dataset\n",
        "\n",
        "test_predict = model.predict(x_test)\n",
        "test_predictions = (test_predict+1).reshape(1,-1) * np.cumprod(y_test+1)\n",
        "\n",
        "train_predict = model.predict(x_train)\n",
        "train_predictions = (train_predict+1).reshape(1,-1) * np.cumprod(y_train+1)\n",
        "\n",
        "\n",
        "\n",
        "plt.plot(stock_data[:training_data_len- input_size].index, np.cumprod(y_train+1), label=\"Training Data\")\n",
        "plt.plot(stock_data[:training_data_len- input_size].index, train_predictions[0], label=\"Training Predictions\")\n",
        "end_val = np.cumprod(y_train+1)[-1]\n",
        "test_predict = model.predict(x_test)\n",
        "test_predictions = (test_predict+1).reshape(1,-1) * (np.cumprod((y_test+1))*end_val)\n",
        "plt.plot(stock_data[training_data_len+1:].index, np.cumprod((y_test+1))*end_val,label=\"Test Data\")\n",
        "plt.plot(stock_data[training_data_len+1:].index, test_predictions[0], label=\"Test Predictions\")\n",
        "plt.xlabel(\"Date\")\n",
        "plt.ylabel(\"Stock Price\")\n",
        "plt.legend()\n",
        "plt.show()"
      ],
      "metadata": {
        "id": "d698mdExtfHp"
      },
      "execution_count": null,
      "outputs": []
    },
    {
      "cell_type": "markdown",
      "source": [
        "#5.) Write an observation/conclusion about the graphs from Q4 and Q3"
      ],
      "metadata": {
        "id": "bK_jyyEEtTUB"
      }
    },
    {
      "cell_type": "markdown",
      "source": [
        "I got In-Sample accuracy of 51.62%, which means that the model was able to predict the movement of the stock prices in the training set with an accuracy of 51.62%. This is slightly better than random guessing, which would have a 50% accuracy. \n",
        "\n",
        "The result of In-Sample Random Walk accuracy means that if we had simply assumed that the stock price movement in the training set was the same as the previous day's movement, we would have achieved an accuracy of 50.31%. This suggests that the model is not performing significantly better than a random walk assumption in the training set.\n",
        "\n",
        "However, I got 0 for Out-of-Sample accuracy. I think it is because that the model was not able to predict the movement of the stock prices in the test set. The accuracy of 0% suggests that the model is not able to generalize well to unseen data. Maybe I should look for better hyperparameters or change dataset.\n",
        "\n",
        "And I got 100 for Out-of-Sample Random-Walk accuracy, and it suggests that the model is not able to outperform a random walk forecast.This could be due to a variety of factors, such as insufficient data, weak signals in the data, or inappropriate modeling assumptions. "
      ],
      "metadata": {
        "id": "sVYvd9gl88E_"
      }
    },
    {
      "cell_type": "markdown",
      "source": [
        "# 6.) Create a parameter for number of lags in your input layer. Do a 3-fold CV to test three different time lags. i.e. Tested using 5,10,20 days of previous price data to forecast"
      ],
      "metadata": {
        "id": "pFtrp-lmtw6t"
      }
    },
    {
      "cell_type": "code",
      "source": [
        "from sklearn.model_selection import GridSearchCV\n",
        "from keras.wrappers.scikit_learn import KerasClassifier\n",
        "from keras.wrappers.scikit_learn import KerasRegressor\n",
        "\n",
        "# Define the Keras model\n",
        "###Edit here to create your optimizer\n",
        "def create_model(input_size):\n",
        "    model = Sequential()\n",
        "    model.add(Dense(10, input_dim=input_size, activation='sigmoid'))\n",
        "    model.add(Dense(1, activation='sigmoid'))\n",
        "    model.compile(loss='binary_crossentropy', optimizer='adam', metrics=['accuracy'])\n",
        "    return(model)\n",
        "\n",
        "# Wrap the Keras model in a scikit-learn compatible estimator\n",
        "model = KerasRegressor(build_fn=create_model, verbose=0)\n",
        "\n",
        "# Define the hyperparameters to search over\n",
        "####EXAMPLE###\n",
        "param_grid = {'batch_size': [10, 20, 100],\n",
        "              'epochs': [10],\n",
        "              'input_size':[5,10,20]}\n",
        "\n",
        "# Perform the grid search over the hyperparameters\n",
        "\n",
        "grid = GridSearchCV(estimator=model, param_grid=param_grid, n_jobs=-1, cv=3)\n",
        "grid_result = grid.fit(x_train, y_train)\n",
        "\n",
        "# Print the results\n",
        "print(\"Best: %f using %s\" % (grid_result.best_score_, grid_result.best_params_))"
      ],
      "metadata": {
        "id": "kEOQ6TO0-Fnw",
        "colab": {
          "base_uri": "https://localhost:8080/"
        },
        "outputId": "a064b065-56b4-4789-cc0f-cc1ad7ef0c7a"
      },
      "execution_count": 36,
      "outputs": [
        {
          "output_type": "stream",
          "name": "stderr",
          "text": [
            "<ipython-input-36-8546214b1de0>:15: DeprecationWarning: KerasRegressor is deprecated, use Sci-Keras (https://github.com/adriangb/scikeras) instead. See https://www.adriangb.com/scikeras/stable/migration.html for help migrating.\n",
            "  model = KerasRegressor(build_fn=create_model, verbose=0)\n",
            "/usr/local/lib/python3.8/dist-packages/sklearn/model_selection/_validation.py:372: FitFailedWarning: \n",
            "18 fits failed out of a total of 27.\n",
            "The score on these train-test partitions for these parameters will be set to nan.\n",
            "If these failures are not expected, you can try to debug them by setting error_score='raise'.\n",
            "\n",
            "Below are more details about the failures:\n",
            "--------------------------------------------------------------------------------\n",
            "1 fits failed with the following error:\n",
            "Traceback (most recent call last):\n",
            "  File \"/usr/local/lib/python3.8/dist-packages/sklearn/model_selection/_validation.py\", line 680, in _fit_and_score\n",
            "    estimator.fit(X_train, y_train, **fit_params)\n",
            "  File \"/usr/local/lib/python3.8/dist-packages/keras/wrappers/scikit_learn.py\", line 175, in fit\n",
            "    history = self.model.fit(x, y, **fit_args)\n",
            "  File \"/usr/local/lib/python3.8/dist-packages/keras/utils/traceback_utils.py\", line 70, in error_handler\n",
            "    raise e.with_traceback(filtered_tb) from None\n",
            "  File \"/tmp/__autograph_generated_fileo0u91gb3.py\", line 15, in tf__train_function\n",
            "    retval_ = ag__.converted_call(ag__.ld(step_function), (ag__.ld(self), ag__.ld(iterator)), None, fscope)\n",
            "ValueError: in user code:\n",
            "\n",
            "    File \"/usr/local/lib/python3.8/dist-packages/keras/engine/training.py\", line 1249, in train_function  *\n",
            "        return step_function(self, iterator)\n",
            "    File \"/usr/local/lib/python3.8/dist-packages/keras/engine/training.py\", line 1233, in step_function  **\n",
            "        outputs = model.distribute_strategy.run(run_step, args=(data,))\n",
            "    File \"/usr/local/lib/python3.8/dist-packages/keras/engine/training.py\", line 1222, in run_step  **\n",
            "        outputs = model.train_step(data)\n",
            "    File \"/usr/local/lib/python3.8/dist-packages/keras/engine/training.py\", line 1023, in train_step\n",
            "        y_pred = self(x, training=True)\n",
            "    File \"/usr/local/lib/python3.8/dist-packages/keras/utils/traceback_utils.py\", line 70, in error_handler\n",
            "        raise e.with_traceback(filtered_tb) from None\n",
            "    File \"/usr/local/lib/python3.8/dist-packages/keras/engine/input_spec.py\", line 295, in assert_input_compatibility\n",
            "        raise ValueError(\n",
            "\n",
            "    ValueError: Input 0 of layer \"sequential_19\" is incompatible with the layer: expected shape=(None, 10), found shape=(None, 5, 1)\n",
            "\n",
            "\n",
            "--------------------------------------------------------------------------------\n",
            "1 fits failed with the following error:\n",
            "Traceback (most recent call last):\n",
            "  File \"/usr/local/lib/python3.8/dist-packages/sklearn/model_selection/_validation.py\", line 680, in _fit_and_score\n",
            "    estimator.fit(X_train, y_train, **fit_params)\n",
            "  File \"/usr/local/lib/python3.8/dist-packages/keras/wrappers/scikit_learn.py\", line 175, in fit\n",
            "    history = self.model.fit(x, y, **fit_args)\n",
            "  File \"/usr/local/lib/python3.8/dist-packages/keras/utils/traceback_utils.py\", line 70, in error_handler\n",
            "    raise e.with_traceback(filtered_tb) from None\n",
            "  File \"/tmp/__autograph_generated_fileo0u91gb3.py\", line 15, in tf__train_function\n",
            "    retval_ = ag__.converted_call(ag__.ld(step_function), (ag__.ld(self), ag__.ld(iterator)), None, fscope)\n",
            "ValueError: in user code:\n",
            "\n",
            "    File \"/usr/local/lib/python3.8/dist-packages/keras/engine/training.py\", line 1249, in train_function  *\n",
            "        return step_function(self, iterator)\n",
            "    File \"/usr/local/lib/python3.8/dist-packages/keras/engine/training.py\", line 1233, in step_function  **\n",
            "        outputs = model.distribute_strategy.run(run_step, args=(data,))\n",
            "    File \"/usr/local/lib/python3.8/dist-packages/keras/engine/training.py\", line 1222, in run_step  **\n",
            "        outputs = model.train_step(data)\n",
            "    File \"/usr/local/lib/python3.8/dist-packages/keras/engine/training.py\", line 1023, in train_step\n",
            "        y_pred = self(x, training=True)\n",
            "    File \"/usr/local/lib/python3.8/dist-packages/keras/utils/traceback_utils.py\", line 70, in error_handler\n",
            "        raise e.with_traceback(filtered_tb) from None\n",
            "    File \"/usr/local/lib/python3.8/dist-packages/keras/engine/input_spec.py\", line 295, in assert_input_compatibility\n",
            "        raise ValueError(\n",
            "\n",
            "    ValueError: Input 0 of layer \"sequential_20\" is incompatible with the layer: expected shape=(None, 10), found shape=(None, 5, 1)\n",
            "\n",
            "\n",
            "--------------------------------------------------------------------------------\n",
            "1 fits failed with the following error:\n",
            "Traceback (most recent call last):\n",
            "  File \"/usr/local/lib/python3.8/dist-packages/sklearn/model_selection/_validation.py\", line 680, in _fit_and_score\n",
            "    estimator.fit(X_train, y_train, **fit_params)\n",
            "  File \"/usr/local/lib/python3.8/dist-packages/keras/wrappers/scikit_learn.py\", line 175, in fit\n",
            "    history = self.model.fit(x, y, **fit_args)\n",
            "  File \"/usr/local/lib/python3.8/dist-packages/keras/utils/traceback_utils.py\", line 70, in error_handler\n",
            "    raise e.with_traceback(filtered_tb) from None\n",
            "  File \"/tmp/__autograph_generated_fileo0u91gb3.py\", line 15, in tf__train_function\n",
            "    retval_ = ag__.converted_call(ag__.ld(step_function), (ag__.ld(self), ag__.ld(iterator)), None, fscope)\n",
            "ValueError: in user code:\n",
            "\n",
            "    File \"/usr/local/lib/python3.8/dist-packages/keras/engine/training.py\", line 1249, in train_function  *\n",
            "        return step_function(self, iterator)\n",
            "    File \"/usr/local/lib/python3.8/dist-packages/keras/engine/training.py\", line 1233, in step_function  **\n",
            "        outputs = model.distribute_strategy.run(run_step, args=(data,))\n",
            "    File \"/usr/local/lib/python3.8/dist-packages/keras/engine/training.py\", line 1222, in run_step  **\n",
            "        outputs = model.train_step(data)\n",
            "    File \"/usr/local/lib/python3.8/dist-packages/keras/engine/training.py\", line 1023, in train_step\n",
            "        y_pred = self(x, training=True)\n",
            "    File \"/usr/local/lib/python3.8/dist-packages/keras/utils/traceback_utils.py\", line 70, in error_handler\n",
            "        raise e.with_traceback(filtered_tb) from None\n",
            "    File \"/usr/local/lib/python3.8/dist-packages/keras/engine/input_spec.py\", line 295, in assert_input_compatibility\n",
            "        raise ValueError(\n",
            "\n",
            "    ValueError: Input 0 of layer \"sequential_21\" is incompatible with the layer: expected shape=(None, 10), found shape=(10, 5, 1)\n",
            "\n",
            "\n",
            "--------------------------------------------------------------------------------\n",
            "1 fits failed with the following error:\n",
            "Traceback (most recent call last):\n",
            "  File \"/usr/local/lib/python3.8/dist-packages/sklearn/model_selection/_validation.py\", line 680, in _fit_and_score\n",
            "    estimator.fit(X_train, y_train, **fit_params)\n",
            "  File \"/usr/local/lib/python3.8/dist-packages/keras/wrappers/scikit_learn.py\", line 175, in fit\n",
            "    history = self.model.fit(x, y, **fit_args)\n",
            "  File \"/usr/local/lib/python3.8/dist-packages/keras/utils/traceback_utils.py\", line 70, in error_handler\n",
            "    raise e.with_traceback(filtered_tb) from None\n",
            "  File \"/tmp/__autograph_generated_fileo0u91gb3.py\", line 15, in tf__train_function\n",
            "    retval_ = ag__.converted_call(ag__.ld(step_function), (ag__.ld(self), ag__.ld(iterator)), None, fscope)\n",
            "ValueError: in user code:\n",
            "\n",
            "    File \"/usr/local/lib/python3.8/dist-packages/keras/engine/training.py\", line 1249, in train_function  *\n",
            "        return step_function(self, iterator)\n",
            "    File \"/usr/local/lib/python3.8/dist-packages/keras/engine/training.py\", line 1233, in step_function  **\n",
            "        outputs = model.distribute_strategy.run(run_step, args=(data,))\n",
            "    File \"/usr/local/lib/python3.8/dist-packages/keras/engine/training.py\", line 1222, in run_step  **\n",
            "        outputs = model.train_step(data)\n",
            "    File \"/usr/local/lib/python3.8/dist-packages/keras/engine/training.py\", line 1023, in train_step\n",
            "        y_pred = self(x, training=True)\n",
            "    File \"/usr/local/lib/python3.8/dist-packages/keras/utils/traceback_utils.py\", line 70, in error_handler\n",
            "        raise e.with_traceback(filtered_tb) from None\n",
            "    File \"/usr/local/lib/python3.8/dist-packages/keras/engine/input_spec.py\", line 295, in assert_input_compatibility\n",
            "        raise ValueError(\n",
            "\n",
            "    ValueError: Input 0 of layer \"sequential_22\" is incompatible with the layer: expected shape=(None, 20), found shape=(None, 5, 1)\n",
            "\n",
            "\n",
            "--------------------------------------------------------------------------------\n",
            "1 fits failed with the following error:\n",
            "Traceback (most recent call last):\n",
            "  File \"/usr/local/lib/python3.8/dist-packages/sklearn/model_selection/_validation.py\", line 680, in _fit_and_score\n",
            "    estimator.fit(X_train, y_train, **fit_params)\n",
            "  File \"/usr/local/lib/python3.8/dist-packages/keras/wrappers/scikit_learn.py\", line 175, in fit\n",
            "    history = self.model.fit(x, y, **fit_args)\n",
            "  File \"/usr/local/lib/python3.8/dist-packages/keras/utils/traceback_utils.py\", line 70, in error_handler\n",
            "    raise e.with_traceback(filtered_tb) from None\n",
            "  File \"/tmp/__autograph_generated_fileo0u91gb3.py\", line 15, in tf__train_function\n",
            "    retval_ = ag__.converted_call(ag__.ld(step_function), (ag__.ld(self), ag__.ld(iterator)), None, fscope)\n",
            "ValueError: in user code:\n",
            "\n",
            "    File \"/usr/local/lib/python3.8/dist-packages/keras/engine/training.py\", line 1249, in train_function  *\n",
            "        return step_function(self, iterator)\n",
            "    File \"/usr/local/lib/python3.8/dist-packages/keras/engine/training.py\", line 1233, in step_function  **\n",
            "        outputs = model.distribute_strategy.run(run_step, args=(data,))\n",
            "    File \"/usr/local/lib/python3.8/dist-packages/keras/engine/training.py\", line 1222, in run_step  **\n",
            "        outputs = model.train_step(data)\n",
            "    File \"/usr/local/lib/python3.8/dist-packages/keras/engine/training.py\", line 1023, in train_step\n",
            "        y_pred = self(x, training=True)\n",
            "    File \"/usr/local/lib/python3.8/dist-packages/keras/utils/traceback_utils.py\", line 70, in error_handler\n",
            "        raise e.with_traceback(filtered_tb) from None\n",
            "    File \"/usr/local/lib/python3.8/dist-packages/keras/engine/input_spec.py\", line 295, in assert_input_compatibility\n",
            "        raise ValueError(\n",
            "\n",
            "    ValueError: Input 0 of layer \"sequential_23\" is incompatible with the layer: expected shape=(None, 20), found shape=(None, 5, 1)\n",
            "\n",
            "\n",
            "--------------------------------------------------------------------------------\n",
            "1 fits failed with the following error:\n",
            "Traceback (most recent call last):\n",
            "  File \"/usr/local/lib/python3.8/dist-packages/sklearn/model_selection/_validation.py\", line 680, in _fit_and_score\n",
            "    estimator.fit(X_train, y_train, **fit_params)\n",
            "  File \"/usr/local/lib/python3.8/dist-packages/keras/wrappers/scikit_learn.py\", line 175, in fit\n",
            "    history = self.model.fit(x, y, **fit_args)\n",
            "  File \"/usr/local/lib/python3.8/dist-packages/keras/utils/traceback_utils.py\", line 70, in error_handler\n",
            "    raise e.with_traceback(filtered_tb) from None\n",
            "  File \"/tmp/__autograph_generated_fileo0u91gb3.py\", line 15, in tf__train_function\n",
            "    retval_ = ag__.converted_call(ag__.ld(step_function), (ag__.ld(self), ag__.ld(iterator)), None, fscope)\n",
            "ValueError: in user code:\n",
            "\n",
            "    File \"/usr/local/lib/python3.8/dist-packages/keras/engine/training.py\", line 1249, in train_function  *\n",
            "        return step_function(self, iterator)\n",
            "    File \"/usr/local/lib/python3.8/dist-packages/keras/engine/training.py\", line 1233, in step_function  **\n",
            "        outputs = model.distribute_strategy.run(run_step, args=(data,))\n",
            "    File \"/usr/local/lib/python3.8/dist-packages/keras/engine/training.py\", line 1222, in run_step  **\n",
            "        outputs = model.train_step(data)\n",
            "    File \"/usr/local/lib/python3.8/dist-packages/keras/engine/training.py\", line 1023, in train_step\n",
            "        y_pred = self(x, training=True)\n",
            "    File \"/usr/local/lib/python3.8/dist-packages/keras/utils/traceback_utils.py\", line 70, in error_handler\n",
            "        raise e.with_traceback(filtered_tb) from None\n",
            "    File \"/usr/local/lib/python3.8/dist-packages/keras/engine/input_spec.py\", line 295, in assert_input_compatibility\n",
            "        raise ValueError(\n",
            "\n",
            "    ValueError: Input 0 of layer \"sequential_24\" is incompatible with the layer: expected shape=(None, 20), found shape=(10, 5, 1)\n",
            "\n",
            "\n",
            "--------------------------------------------------------------------------------\n",
            "1 fits failed with the following error:\n",
            "Traceback (most recent call last):\n",
            "  File \"/usr/local/lib/python3.8/dist-packages/sklearn/model_selection/_validation.py\", line 680, in _fit_and_score\n",
            "    estimator.fit(X_train, y_train, **fit_params)\n",
            "  File \"/usr/local/lib/python3.8/dist-packages/keras/wrappers/scikit_learn.py\", line 175, in fit\n",
            "    history = self.model.fit(x, y, **fit_args)\n",
            "  File \"/usr/local/lib/python3.8/dist-packages/keras/utils/traceback_utils.py\", line 70, in error_handler\n",
            "    raise e.with_traceback(filtered_tb) from None\n",
            "  File \"/tmp/__autograph_generated_fileo0u91gb3.py\", line 15, in tf__train_function\n",
            "    retval_ = ag__.converted_call(ag__.ld(step_function), (ag__.ld(self), ag__.ld(iterator)), None, fscope)\n",
            "ValueError: in user code:\n",
            "\n",
            "    File \"/usr/local/lib/python3.8/dist-packages/keras/engine/training.py\", line 1249, in train_function  *\n",
            "        return step_function(self, iterator)\n",
            "    File \"/usr/local/lib/python3.8/dist-packages/keras/engine/training.py\", line 1233, in step_function  **\n",
            "        outputs = model.distribute_strategy.run(run_step, args=(data,))\n",
            "    File \"/usr/local/lib/python3.8/dist-packages/keras/engine/training.py\", line 1222, in run_step  **\n",
            "        outputs = model.train_step(data)\n",
            "    File \"/usr/local/lib/python3.8/dist-packages/keras/engine/training.py\", line 1023, in train_step\n",
            "        y_pred = self(x, training=True)\n",
            "    File \"/usr/local/lib/python3.8/dist-packages/keras/utils/traceback_utils.py\", line 70, in error_handler\n",
            "        raise e.with_traceback(filtered_tb) from None\n",
            "    File \"/usr/local/lib/python3.8/dist-packages/keras/engine/input_spec.py\", line 295, in assert_input_compatibility\n",
            "        raise ValueError(\n",
            "\n",
            "    ValueError: Input 0 of layer \"sequential_26\" is incompatible with the layer: expected shape=(None, 10), found shape=(None, 5, 1)\n",
            "\n",
            "\n",
            "--------------------------------------------------------------------------------\n",
            "1 fits failed with the following error:\n",
            "Traceback (most recent call last):\n",
            "  File \"/usr/local/lib/python3.8/dist-packages/sklearn/model_selection/_validation.py\", line 680, in _fit_and_score\n",
            "    estimator.fit(X_train, y_train, **fit_params)\n",
            "  File \"/usr/local/lib/python3.8/dist-packages/keras/wrappers/scikit_learn.py\", line 175, in fit\n",
            "    history = self.model.fit(x, y, **fit_args)\n",
            "  File \"/usr/local/lib/python3.8/dist-packages/keras/utils/traceback_utils.py\", line 70, in error_handler\n",
            "    raise e.with_traceback(filtered_tb) from None\n",
            "  File \"/tmp/__autograph_generated_fileo0u91gb3.py\", line 15, in tf__train_function\n",
            "    retval_ = ag__.converted_call(ag__.ld(step_function), (ag__.ld(self), ag__.ld(iterator)), None, fscope)\n",
            "ValueError: in user code:\n",
            "\n",
            "    File \"/usr/local/lib/python3.8/dist-packages/keras/engine/training.py\", line 1249, in train_function  *\n",
            "        return step_function(self, iterator)\n",
            "    File \"/usr/local/lib/python3.8/dist-packages/keras/engine/training.py\", line 1233, in step_function  **\n",
            "        outputs = model.distribute_strategy.run(run_step, args=(data,))\n",
            "    File \"/usr/local/lib/python3.8/dist-packages/keras/engine/training.py\", line 1222, in run_step  **\n",
            "        outputs = model.train_step(data)\n",
            "    File \"/usr/local/lib/python3.8/dist-packages/keras/engine/training.py\", line 1023, in train_step\n",
            "        y_pred = self(x, training=True)\n",
            "    File \"/usr/local/lib/python3.8/dist-packages/keras/utils/traceback_utils.py\", line 70, in error_handler\n",
            "        raise e.with_traceback(filtered_tb) from None\n",
            "    File \"/usr/local/lib/python3.8/dist-packages/keras/engine/input_spec.py\", line 295, in assert_input_compatibility\n",
            "        raise ValueError(\n",
            "\n",
            "    ValueError: Input 0 of layer \"sequential_27\" is incompatible with the layer: expected shape=(None, 10), found shape=(None, 5, 1)\n",
            "\n",
            "\n",
            "--------------------------------------------------------------------------------\n",
            "1 fits failed with the following error:\n",
            "Traceback (most recent call last):\n",
            "  File \"/usr/local/lib/python3.8/dist-packages/sklearn/model_selection/_validation.py\", line 680, in _fit_and_score\n",
            "    estimator.fit(X_train, y_train, **fit_params)\n",
            "  File \"/usr/local/lib/python3.8/dist-packages/keras/wrappers/scikit_learn.py\", line 175, in fit\n",
            "    history = self.model.fit(x, y, **fit_args)\n",
            "  File \"/usr/local/lib/python3.8/dist-packages/keras/utils/traceback_utils.py\", line 70, in error_handler\n",
            "    raise e.with_traceback(filtered_tb) from None\n",
            "  File \"/tmp/__autograph_generated_fileo0u91gb3.py\", line 15, in tf__train_function\n",
            "    retval_ = ag__.converted_call(ag__.ld(step_function), (ag__.ld(self), ag__.ld(iterator)), None, fscope)\n",
            "ValueError: in user code:\n",
            "\n",
            "    File \"/usr/local/lib/python3.8/dist-packages/keras/engine/training.py\", line 1249, in train_function  *\n",
            "        return step_function(self, iterator)\n",
            "    File \"/usr/local/lib/python3.8/dist-packages/keras/engine/training.py\", line 1233, in step_function  **\n",
            "        outputs = model.distribute_strategy.run(run_step, args=(data,))\n",
            "    File \"/usr/local/lib/python3.8/dist-packages/keras/engine/training.py\", line 1222, in run_step  **\n",
            "        outputs = model.train_step(data)\n",
            "    File \"/usr/local/lib/python3.8/dist-packages/keras/engine/training.py\", line 1023, in train_step\n",
            "        y_pred = self(x, training=True)\n",
            "    File \"/usr/local/lib/python3.8/dist-packages/keras/utils/traceback_utils.py\", line 70, in error_handler\n",
            "        raise e.with_traceback(filtered_tb) from None\n",
            "    File \"/usr/local/lib/python3.8/dist-packages/keras/engine/input_spec.py\", line 295, in assert_input_compatibility\n",
            "        raise ValueError(\n",
            "\n",
            "    ValueError: Input 0 of layer \"sequential_28\" is incompatible with the layer: expected shape=(None, 10), found shape=(None, 5, 1)\n",
            "\n",
            "\n",
            "--------------------------------------------------------------------------------\n",
            "1 fits failed with the following error:\n",
            "Traceback (most recent call last):\n",
            "  File \"/usr/local/lib/python3.8/dist-packages/sklearn/model_selection/_validation.py\", line 680, in _fit_and_score\n",
            "    estimator.fit(X_train, y_train, **fit_params)\n",
            "  File \"/usr/local/lib/python3.8/dist-packages/keras/wrappers/scikit_learn.py\", line 175, in fit\n",
            "    history = self.model.fit(x, y, **fit_args)\n",
            "  File \"/usr/local/lib/python3.8/dist-packages/keras/utils/traceback_utils.py\", line 70, in error_handler\n",
            "    raise e.with_traceback(filtered_tb) from None\n",
            "  File \"/tmp/__autograph_generated_fileo0u91gb3.py\", line 15, in tf__train_function\n",
            "    retval_ = ag__.converted_call(ag__.ld(step_function), (ag__.ld(self), ag__.ld(iterator)), None, fscope)\n",
            "ValueError: in user code:\n",
            "\n",
            "    File \"/usr/local/lib/python3.8/dist-packages/keras/engine/training.py\", line 1249, in train_function  *\n",
            "        return step_function(self, iterator)\n",
            "    File \"/usr/local/lib/python3.8/dist-packages/keras/engine/training.py\", line 1233, in step_function  **\n",
            "        outputs = model.distribute_strategy.run(run_step, args=(data,))\n",
            "    File \"/usr/local/lib/python3.8/dist-packages/keras/engine/training.py\", line 1222, in run_step  **\n",
            "        outputs = model.train_step(data)\n",
            "    File \"/usr/local/lib/python3.8/dist-packages/keras/engine/training.py\", line 1023, in train_step\n",
            "        y_pred = self(x, training=True)\n",
            "    File \"/usr/local/lib/python3.8/dist-packages/keras/utils/traceback_utils.py\", line 70, in error_handler\n",
            "        raise e.with_traceback(filtered_tb) from None\n",
            "    File \"/usr/local/lib/python3.8/dist-packages/keras/engine/input_spec.py\", line 295, in assert_input_compatibility\n",
            "        raise ValueError(\n",
            "\n",
            "    ValueError: Input 0 of layer \"sequential_29\" is incompatible with the layer: expected shape=(None, 20), found shape=(None, 5, 1)\n",
            "\n",
            "\n",
            "--------------------------------------------------------------------------------\n",
            "1 fits failed with the following error:\n",
            "Traceback (most recent call last):\n",
            "  File \"/usr/local/lib/python3.8/dist-packages/sklearn/model_selection/_validation.py\", line 680, in _fit_and_score\n",
            "    estimator.fit(X_train, y_train, **fit_params)\n",
            "  File \"/usr/local/lib/python3.8/dist-packages/keras/wrappers/scikit_learn.py\", line 175, in fit\n",
            "    history = self.model.fit(x, y, **fit_args)\n",
            "  File \"/usr/local/lib/python3.8/dist-packages/keras/utils/traceback_utils.py\", line 70, in error_handler\n",
            "    raise e.with_traceback(filtered_tb) from None\n",
            "  File \"/tmp/__autograph_generated_fileo0u91gb3.py\", line 15, in tf__train_function\n",
            "    retval_ = ag__.converted_call(ag__.ld(step_function), (ag__.ld(self), ag__.ld(iterator)), None, fscope)\n",
            "ValueError: in user code:\n",
            "\n",
            "    File \"/usr/local/lib/python3.8/dist-packages/keras/engine/training.py\", line 1249, in train_function  *\n",
            "        return step_function(self, iterator)\n",
            "    File \"/usr/local/lib/python3.8/dist-packages/keras/engine/training.py\", line 1233, in step_function  **\n",
            "        outputs = model.distribute_strategy.run(run_step, args=(data,))\n",
            "    File \"/usr/local/lib/python3.8/dist-packages/keras/engine/training.py\", line 1222, in run_step  **\n",
            "        outputs = model.train_step(data)\n",
            "    File \"/usr/local/lib/python3.8/dist-packages/keras/engine/training.py\", line 1023, in train_step\n",
            "        y_pred = self(x, training=True)\n",
            "    File \"/usr/local/lib/python3.8/dist-packages/keras/utils/traceback_utils.py\", line 70, in error_handler\n",
            "        raise e.with_traceback(filtered_tb) from None\n",
            "    File \"/usr/local/lib/python3.8/dist-packages/keras/engine/input_spec.py\", line 295, in assert_input_compatibility\n",
            "        raise ValueError(\n",
            "\n",
            "    ValueError: Input 0 of layer \"sequential_30\" is incompatible with the layer: expected shape=(None, 20), found shape=(None, 5, 1)\n",
            "\n",
            "\n",
            "--------------------------------------------------------------------------------\n",
            "1 fits failed with the following error:\n",
            "Traceback (most recent call last):\n",
            "  File \"/usr/local/lib/python3.8/dist-packages/sklearn/model_selection/_validation.py\", line 680, in _fit_and_score\n",
            "    estimator.fit(X_train, y_train, **fit_params)\n",
            "  File \"/usr/local/lib/python3.8/dist-packages/keras/wrappers/scikit_learn.py\", line 175, in fit\n",
            "    history = self.model.fit(x, y, **fit_args)\n",
            "  File \"/usr/local/lib/python3.8/dist-packages/keras/utils/traceback_utils.py\", line 70, in error_handler\n",
            "    raise e.with_traceback(filtered_tb) from None\n",
            "  File \"/tmp/__autograph_generated_fileo0u91gb3.py\", line 15, in tf__train_function\n",
            "    retval_ = ag__.converted_call(ag__.ld(step_function), (ag__.ld(self), ag__.ld(iterator)), None, fscope)\n",
            "ValueError: in user code:\n",
            "\n",
            "    File \"/usr/local/lib/python3.8/dist-packages/keras/engine/training.py\", line 1249, in train_function  *\n",
            "        return step_function(self, iterator)\n",
            "    File \"/usr/local/lib/python3.8/dist-packages/keras/engine/training.py\", line 1233, in step_function  **\n",
            "        outputs = model.distribute_strategy.run(run_step, args=(data,))\n",
            "    File \"/usr/local/lib/python3.8/dist-packages/keras/engine/training.py\", line 1222, in run_step  **\n",
            "        outputs = model.train_step(data)\n",
            "    File \"/usr/local/lib/python3.8/dist-packages/keras/engine/training.py\", line 1023, in train_step\n",
            "        y_pred = self(x, training=True)\n",
            "    File \"/usr/local/lib/python3.8/dist-packages/keras/utils/traceback_utils.py\", line 70, in error_handler\n",
            "        raise e.with_traceback(filtered_tb) from None\n",
            "    File \"/usr/local/lib/python3.8/dist-packages/keras/engine/input_spec.py\", line 295, in assert_input_compatibility\n",
            "        raise ValueError(\n",
            "\n",
            "    ValueError: Input 0 of layer \"sequential_31\" is incompatible with the layer: expected shape=(None, 20), found shape=(None, 5, 1)\n",
            "\n",
            "\n",
            "--------------------------------------------------------------------------------\n",
            "1 fits failed with the following error:\n",
            "Traceback (most recent call last):\n",
            "  File \"/usr/local/lib/python3.8/dist-packages/sklearn/model_selection/_validation.py\", line 680, in _fit_and_score\n",
            "    estimator.fit(X_train, y_train, **fit_params)\n",
            "  File \"/usr/local/lib/python3.8/dist-packages/keras/wrappers/scikit_learn.py\", line 175, in fit\n",
            "    history = self.model.fit(x, y, **fit_args)\n",
            "  File \"/usr/local/lib/python3.8/dist-packages/keras/utils/traceback_utils.py\", line 70, in error_handler\n",
            "    raise e.with_traceback(filtered_tb) from None\n",
            "  File \"/tmp/__autograph_generated_filel6zfjria.py\", line 15, in tf__train_function\n",
            "    retval_ = ag__.converted_call(ag__.ld(step_function), (ag__.ld(self), ag__.ld(iterator)), None, fscope)\n",
            "ValueError: in user code:\n",
            "\n",
            "    File \"/usr/local/lib/python3.8/dist-packages/keras/engine/training.py\", line 1249, in train_function  *\n",
            "        return step_function(self, iterator)\n",
            "    File \"/usr/local/lib/python3.8/dist-packages/keras/engine/training.py\", line 1233, in step_function  **\n",
            "        outputs = model.distribute_strategy.run(run_step, args=(data,))\n",
            "    File \"/usr/local/lib/python3.8/dist-packages/keras/engine/training.py\", line 1222, in run_step  **\n",
            "        outputs = model.train_step(data)\n",
            "    File \"/usr/local/lib/python3.8/dist-packages/keras/engine/training.py\", line 1023, in train_step\n",
            "        y_pred = self(x, training=True)\n",
            "    File \"/usr/local/lib/python3.8/dist-packages/keras/utils/traceback_utils.py\", line 70, in error_handler\n",
            "        raise e.with_traceback(filtered_tb) from None\n",
            "    File \"/usr/local/lib/python3.8/dist-packages/keras/engine/input_spec.py\", line 295, in assert_input_compatibility\n",
            "        raise ValueError(\n",
            "\n",
            "    ValueError: Input 0 of layer \"sequential_41\" is incompatible with the layer: expected shape=(None, 10), found shape=(None, 5, 1)\n",
            "\n",
            "\n",
            "--------------------------------------------------------------------------------\n",
            "1 fits failed with the following error:\n",
            "Traceback (most recent call last):\n",
            "  File \"/usr/local/lib/python3.8/dist-packages/sklearn/model_selection/_validation.py\", line 680, in _fit_and_score\n",
            "    estimator.fit(X_train, y_train, **fit_params)\n",
            "  File \"/usr/local/lib/python3.8/dist-packages/keras/wrappers/scikit_learn.py\", line 175, in fit\n",
            "    history = self.model.fit(x, y, **fit_args)\n",
            "  File \"/usr/local/lib/python3.8/dist-packages/keras/utils/traceback_utils.py\", line 70, in error_handler\n",
            "    raise e.with_traceback(filtered_tb) from None\n",
            "  File \"/tmp/__autograph_generated_filel6zfjria.py\", line 15, in tf__train_function\n",
            "    retval_ = ag__.converted_call(ag__.ld(step_function), (ag__.ld(self), ag__.ld(iterator)), None, fscope)\n",
            "ValueError: in user code:\n",
            "\n",
            "    File \"/usr/local/lib/python3.8/dist-packages/keras/engine/training.py\", line 1249, in train_function  *\n",
            "        return step_function(self, iterator)\n",
            "    File \"/usr/local/lib/python3.8/dist-packages/keras/engine/training.py\", line 1233, in step_function  **\n",
            "        outputs = model.distribute_strategy.run(run_step, args=(data,))\n",
            "    File \"/usr/local/lib/python3.8/dist-packages/keras/engine/training.py\", line 1222, in run_step  **\n",
            "        outputs = model.train_step(data)\n",
            "    File \"/usr/local/lib/python3.8/dist-packages/keras/engine/training.py\", line 1023, in train_step\n",
            "        y_pred = self(x, training=True)\n",
            "    File \"/usr/local/lib/python3.8/dist-packages/keras/utils/traceback_utils.py\", line 70, in error_handler\n",
            "        raise e.with_traceback(filtered_tb) from None\n",
            "    File \"/usr/local/lib/python3.8/dist-packages/keras/engine/input_spec.py\", line 295, in assert_input_compatibility\n",
            "        raise ValueError(\n",
            "\n",
            "    ValueError: Input 0 of layer \"sequential_42\" is incompatible with the layer: expected shape=(None, 10), found shape=(None, 5, 1)\n",
            "\n",
            "\n",
            "--------------------------------------------------------------------------------\n",
            "1 fits failed with the following error:\n",
            "Traceback (most recent call last):\n",
            "  File \"/usr/local/lib/python3.8/dist-packages/sklearn/model_selection/_validation.py\", line 680, in _fit_and_score\n",
            "    estimator.fit(X_train, y_train, **fit_params)\n",
            "  File \"/usr/local/lib/python3.8/dist-packages/keras/wrappers/scikit_learn.py\", line 175, in fit\n",
            "    history = self.model.fit(x, y, **fit_args)\n",
            "  File \"/usr/local/lib/python3.8/dist-packages/keras/utils/traceback_utils.py\", line 70, in error_handler\n",
            "    raise e.with_traceback(filtered_tb) from None\n",
            "  File \"/tmp/__autograph_generated_filel6zfjria.py\", line 15, in tf__train_function\n",
            "    retval_ = ag__.converted_call(ag__.ld(step_function), (ag__.ld(self), ag__.ld(iterator)), None, fscope)\n",
            "ValueError: in user code:\n",
            "\n",
            "    File \"/usr/local/lib/python3.8/dist-packages/keras/engine/training.py\", line 1249, in train_function  *\n",
            "        return step_function(self, iterator)\n",
            "    File \"/usr/local/lib/python3.8/dist-packages/keras/engine/training.py\", line 1233, in step_function  **\n",
            "        outputs = model.distribute_strategy.run(run_step, args=(data,))\n",
            "    File \"/usr/local/lib/python3.8/dist-packages/keras/engine/training.py\", line 1222, in run_step  **\n",
            "        outputs = model.train_step(data)\n",
            "    File \"/usr/local/lib/python3.8/dist-packages/keras/engine/training.py\", line 1023, in train_step\n",
            "        y_pred = self(x, training=True)\n",
            "    File \"/usr/local/lib/python3.8/dist-packages/keras/utils/traceback_utils.py\", line 70, in error_handler\n",
            "        raise e.with_traceback(filtered_tb) from None\n",
            "    File \"/usr/local/lib/python3.8/dist-packages/keras/engine/input_spec.py\", line 295, in assert_input_compatibility\n",
            "        raise ValueError(\n",
            "\n",
            "    ValueError: Input 0 of layer \"sequential_43\" is incompatible with the layer: expected shape=(None, 10), found shape=(None, 5, 1)\n",
            "\n",
            "\n",
            "--------------------------------------------------------------------------------\n",
            "1 fits failed with the following error:\n",
            "Traceback (most recent call last):\n",
            "  File \"/usr/local/lib/python3.8/dist-packages/sklearn/model_selection/_validation.py\", line 680, in _fit_and_score\n",
            "    estimator.fit(X_train, y_train, **fit_params)\n",
            "  File \"/usr/local/lib/python3.8/dist-packages/keras/wrappers/scikit_learn.py\", line 175, in fit\n",
            "    history = self.model.fit(x, y, **fit_args)\n",
            "  File \"/usr/local/lib/python3.8/dist-packages/keras/utils/traceback_utils.py\", line 70, in error_handler\n",
            "    raise e.with_traceback(filtered_tb) from None\n",
            "  File \"/tmp/__autograph_generated_filel6zfjria.py\", line 15, in tf__train_function\n",
            "    retval_ = ag__.converted_call(ag__.ld(step_function), (ag__.ld(self), ag__.ld(iterator)), None, fscope)\n",
            "ValueError: in user code:\n",
            "\n",
            "    File \"/usr/local/lib/python3.8/dist-packages/keras/engine/training.py\", line 1249, in train_function  *\n",
            "        return step_function(self, iterator)\n",
            "    File \"/usr/local/lib/python3.8/dist-packages/keras/engine/training.py\", line 1233, in step_function  **\n",
            "        outputs = model.distribute_strategy.run(run_step, args=(data,))\n",
            "    File \"/usr/local/lib/python3.8/dist-packages/keras/engine/training.py\", line 1222, in run_step  **\n",
            "        outputs = model.train_step(data)\n",
            "    File \"/usr/local/lib/python3.8/dist-packages/keras/engine/training.py\", line 1023, in train_step\n",
            "        y_pred = self(x, training=True)\n",
            "    File \"/usr/local/lib/python3.8/dist-packages/keras/utils/traceback_utils.py\", line 70, in error_handler\n",
            "        raise e.with_traceback(filtered_tb) from None\n",
            "    File \"/usr/local/lib/python3.8/dist-packages/keras/engine/input_spec.py\", line 295, in assert_input_compatibility\n",
            "        raise ValueError(\n",
            "\n",
            "    ValueError: Input 0 of layer \"sequential_44\" is incompatible with the layer: expected shape=(None, 20), found shape=(None, 5, 1)\n",
            "\n",
            "\n",
            "--------------------------------------------------------------------------------\n",
            "1 fits failed with the following error:\n",
            "Traceback (most recent call last):\n",
            "  File \"/usr/local/lib/python3.8/dist-packages/sklearn/model_selection/_validation.py\", line 680, in _fit_and_score\n",
            "    estimator.fit(X_train, y_train, **fit_params)\n",
            "  File \"/usr/local/lib/python3.8/dist-packages/keras/wrappers/scikit_learn.py\", line 175, in fit\n",
            "    history = self.model.fit(x, y, **fit_args)\n",
            "  File \"/usr/local/lib/python3.8/dist-packages/keras/utils/traceback_utils.py\", line 70, in error_handler\n",
            "    raise e.with_traceback(filtered_tb) from None\n",
            "  File \"/tmp/__autograph_generated_filel6zfjria.py\", line 15, in tf__train_function\n",
            "    retval_ = ag__.converted_call(ag__.ld(step_function), (ag__.ld(self), ag__.ld(iterator)), None, fscope)\n",
            "ValueError: in user code:\n",
            "\n",
            "    File \"/usr/local/lib/python3.8/dist-packages/keras/engine/training.py\", line 1249, in train_function  *\n",
            "        return step_function(self, iterator)\n",
            "    File \"/usr/local/lib/python3.8/dist-packages/keras/engine/training.py\", line 1233, in step_function  **\n",
            "        outputs = model.distribute_strategy.run(run_step, args=(data,))\n",
            "    File \"/usr/local/lib/python3.8/dist-packages/keras/engine/training.py\", line 1222, in run_step  **\n",
            "        outputs = model.train_step(data)\n",
            "    File \"/usr/local/lib/python3.8/dist-packages/keras/engine/training.py\", line 1023, in train_step\n",
            "        y_pred = self(x, training=True)\n",
            "    File \"/usr/local/lib/python3.8/dist-packages/keras/utils/traceback_utils.py\", line 70, in error_handler\n",
            "        raise e.with_traceback(filtered_tb) from None\n",
            "    File \"/usr/local/lib/python3.8/dist-packages/keras/engine/input_spec.py\", line 295, in assert_input_compatibility\n",
            "        raise ValueError(\n",
            "\n",
            "    ValueError: Input 0 of layer \"sequential_45\" is incompatible with the layer: expected shape=(None, 20), found shape=(None, 5, 1)\n",
            "\n",
            "\n",
            "--------------------------------------------------------------------------------\n",
            "1 fits failed with the following error:\n",
            "Traceback (most recent call last):\n",
            "  File \"/usr/local/lib/python3.8/dist-packages/sklearn/model_selection/_validation.py\", line 680, in _fit_and_score\n",
            "    estimator.fit(X_train, y_train, **fit_params)\n",
            "  File \"/usr/local/lib/python3.8/dist-packages/keras/wrappers/scikit_learn.py\", line 175, in fit\n",
            "    history = self.model.fit(x, y, **fit_args)\n",
            "  File \"/usr/local/lib/python3.8/dist-packages/keras/utils/traceback_utils.py\", line 70, in error_handler\n",
            "    raise e.with_traceback(filtered_tb) from None\n",
            "  File \"/tmp/__autograph_generated_filel6zfjria.py\", line 15, in tf__train_function\n",
            "    retval_ = ag__.converted_call(ag__.ld(step_function), (ag__.ld(self), ag__.ld(iterator)), None, fscope)\n",
            "ValueError: in user code:\n",
            "\n",
            "    File \"/usr/local/lib/python3.8/dist-packages/keras/engine/training.py\", line 1249, in train_function  *\n",
            "        return step_function(self, iterator)\n",
            "    File \"/usr/local/lib/python3.8/dist-packages/keras/engine/training.py\", line 1233, in step_function  **\n",
            "        outputs = model.distribute_strategy.run(run_step, args=(data,))\n",
            "    File \"/usr/local/lib/python3.8/dist-packages/keras/engine/training.py\", line 1222, in run_step  **\n",
            "        outputs = model.train_step(data)\n",
            "    File \"/usr/local/lib/python3.8/dist-packages/keras/engine/training.py\", line 1023, in train_step\n",
            "        y_pred = self(x, training=True)\n",
            "    File \"/usr/local/lib/python3.8/dist-packages/keras/utils/traceback_utils.py\", line 70, in error_handler\n",
            "        raise e.with_traceback(filtered_tb) from None\n",
            "    File \"/usr/local/lib/python3.8/dist-packages/keras/engine/input_spec.py\", line 295, in assert_input_compatibility\n",
            "        raise ValueError(\n",
            "\n",
            "    ValueError: Input 0 of layer \"sequential_46\" is incompatible with the layer: expected shape=(None, 20), found shape=(None, 5, 1)\n",
            "\n",
            "\n",
            "  warnings.warn(some_fits_failed_message, FitFailedWarning)\n",
            "/usr/local/lib/python3.8/dist-packages/sklearn/model_selection/_search.py:969: UserWarning: One or more of the test scores are non-finite: [-0.69330573         nan         nan -0.69377011         nan         nan\n",
            " -0.69410749         nan         nan]\n",
            "  warnings.warn(\n"
          ]
        },
        {
          "output_type": "stream",
          "name": "stdout",
          "text": [
            "Best: -0.693306 using {'batch_size': 10, 'epochs': 10, 'input_size': 5}\n"
          ]
        }
      ]
    },
    {
      "cell_type": "code",
      "source": [],
      "metadata": {
        "id": "QA_gAupmA_8E"
      },
      "execution_count": null,
      "outputs": []
    },
    {
      "cell_type": "code",
      "source": [],
      "metadata": {
        "id": "vfH6js5EB2wu"
      },
      "execution_count": null,
      "outputs": []
    }
  ]
}